INFO:root:Starting experiment
INFO:root:Running 0
INFO:root:Running 1
INFO:root:Running 2
INFO:root:Running 3
INFO:root:Running 4
INFO:root:Running 5
INFO:root:Running 6
INFO:root:Running 7
INFO:root:Running 8
INFO:root:Running 9
INFO:root:Running 10
INFO:root:Running 11
INFO:root:Running 12
INFO:root:Running 13
INFO:root:Running 14
INFO:root:Running 15
INFO:root:Running 16
INFO:root:Running 17
INFO:root:Running 18
INFO:root:Running 19
INFO:root:Running 20
INFO:root:Running 21
INFO:root:Running 22
INFO:root:Running 23
INFO:root:Running 24
INFO:root:Running 25
INFO:root:Running 26
INFO:root:Running 27
INFO:root:Running 28
INFO:root:Running 29
INFO:root:Running 30
INFO:root:Running 31
INFO:root:Running 32
INFO:root:Running 33
INFO:root:Running 34
INFO:root:Running 35
INFO:root:Running 36
INFO:root:Running 37
INFO:root:Running 38
INFO:root:Running 39
INFO:root:Running 40
INFO:root:Running 41
INFO:root:Running 42
INFO:root:Running 43
INFO:root:Running 44
INFO:root:Running 45
INFO:root:Running 46
INFO:root:Running 47
INFO:root:Running 48
INFO:root:Running 49
INFO:root:Running 50
INFO:root:Running 51
INFO:root:Running 52
INFO:root:Running 53
INFO:root:Running 54
INFO:root:Running 55
INFO:root:Running 56
INFO:root:Running 57
INFO:root:Running 58
INFO:root:Running 59
INFO:root:Running 60
INFO:root:Running 61
INFO:root:Running 62
INFO:root:Running 63
INFO:root:Running 64
INFO:root:Running 65
INFO:root:Running 66
INFO:root:Running 67
INFO:root:Running 68
INFO:root:Running 69
INFO:root:Running 70
INFO:root:Running 71
INFO:root:Running 72
INFO:root:Running 73
INFO:root:Running 74
INFO:root:Running 75
INFO:root:Running 76
INFO:root:Running 77
INFO:root:Running 78
INFO:root:Running 79
INFO:root:3 ended
ERROR:concurrent.futures:exception calling callback for <Future at 0x7fac21f4da00 state=finished returned NoneType>
Traceback (most recent call last):
  File "/usr/lib/python3.8/concurrent/futures/_base.py", line 328, in _invoke_callbacks
    callback(self)
  File "/home/glima/Electrical-Behaviour-Prediction/SimulationManager/src/ExperimentManager.py", line 100, in <lambda>
    f.add_done_callback(lambda fut, i=idx: self.__callback(fut, i))
  File "/home/glima/Electrical-Behaviour-Prediction/SimulationManager/src/ExperimentManager.py", line 110, in __callback
    self.__completed.append(tmp_df)
  File "/home/glima/.local/lib/python3.8/site-packages/pandas/core/generic.py", line 5989, in __getattr__
    return object.__getattribute__(self, name)
AttributeError: 'DataFrame' object has no attribute 'append'
INFO:root:1 ended
ERROR:concurrent.futures:exception calling callback for <Future at 0x7fac21f4d640 state=finished returned NoneType>
Traceback (most recent call last):
  File "/usr/lib/python3.8/concurrent/futures/_base.py", line 328, in _invoke_callbacks
    callback(self)
  File "/home/glima/Electrical-Behaviour-Prediction/SimulationManager/src/ExperimentManager.py", line 100, in <lambda>
    f.add_done_callback(lambda fut, i=idx: self.__callback(fut, i))
  File "/home/glima/Electrical-Behaviour-Prediction/SimulationManager/src/ExperimentManager.py", line 110, in __callback
    self.__completed.append(tmp_df)
  File "/home/glima/.local/lib/python3.8/site-packages/pandas/core/generic.py", line 5989, in __getattr__
    return object.__getattribute__(self, name)
AttributeError: 'DataFrame' object has no attribute 'append'
INFO:root:2 ended
ERROR:concurrent.futures:exception calling callback for <Future at 0x7fac21f4d850 state=finished returned NoneType>
Traceback (most recent call last):
  File "/usr/lib/python3.8/concurrent/futures/_base.py", line 328, in _invoke_callbacks
    callback(self)
  File "/home/glima/Electrical-Behaviour-Prediction/SimulationManager/src/ExperimentManager.py", line 100, in <lambda>
    f.add_done_callback(lambda fut, i=idx: self.__callback(fut, i))
  File "/home/glima/Electrical-Behaviour-Prediction/SimulationManager/src/ExperimentManager.py", line 110, in __callback
    self.__completed.append(tmp_df)
  File "/home/glima/.local/lib/python3.8/site-packages/pandas/core/generic.py", line 5989, in __getattr__
    return object.__getattribute__(self, name)
AttributeError: 'DataFrame' object has no attribute 'append'
INFO:root:5 ended
ERROR:concurrent.futures:exception calling callback for <Future at 0x7fac21f4dca0 state=finished returned NoneType>
Traceback (most recent call last):
  File "/usr/lib/python3.8/concurrent/futures/_base.py", line 328, in _invoke_callbacks
    callback(self)
  File "/home/glima/Electrical-Behaviour-Prediction/SimulationManager/src/ExperimentManager.py", line 100, in <lambda>
    f.add_done_callback(lambda fut, i=idx: self.__callback(fut, i))
  File "/home/glima/Electrical-Behaviour-Prediction/SimulationManager/src/ExperimentManager.py", line 110, in __callback
    self.__completed.append(tmp_df)
  File "/home/glima/.local/lib/python3.8/site-packages/pandas/core/generic.py", line 5989, in __getattr__
    return object.__getattribute__(self, name)
AttributeError: 'DataFrame' object has no attribute 'append'
INFO:root:4 ended
ERROR:concurrent.futures:exception calling callback for <Future at 0x7fac21f4db50 state=finished returned NoneType>
Traceback (most recent call last):
  File "/usr/lib/python3.8/concurrent/futures/_base.py", line 328, in _invoke_callbacks
    callback(self)
  File "/home/glima/Electrical-Behaviour-Prediction/SimulationManager/src/ExperimentManager.py", line 100, in <lambda>
    f.add_done_callback(lambda fut, i=idx: self.__callback(fut, i))
  File "/home/glima/Electrical-Behaviour-Prediction/SimulationManager/src/ExperimentManager.py", line 110, in __callback
    self.__completed.append(tmp_df)
  File "/home/glima/.local/lib/python3.8/site-packages/pandas/core/generic.py", line 5989, in __getattr__
    return object.__getattribute__(self, name)
AttributeError: 'DataFrame' object has no attribute 'append'
INFO:root:0 ended
ERROR:concurrent.futures:exception calling callback for <Future at 0x7fac21f3e5e0 state=finished returned NoneType>
Traceback (most recent call last):
  File "/usr/lib/python3.8/concurrent/futures/_base.py", line 328, in _invoke_callbacks
    callback(self)
  File "/home/glima/Electrical-Behaviour-Prediction/SimulationManager/src/ExperimentManager.py", line 100, in <lambda>
    f.add_done_callback(lambda fut, i=idx: self.__callback(fut, i))
  File "/home/glima/Electrical-Behaviour-Prediction/SimulationManager/src/ExperimentManager.py", line 110, in __callback
    self.__completed.append(tmp_df)
  File "/home/glima/.local/lib/python3.8/site-packages/pandas/core/generic.py", line 5989, in __getattr__
    return object.__getattribute__(self, name)
AttributeError: 'DataFrame' object has no attribute 'append'
INFO:root:7 ended
ERROR:concurrent.futures:exception calling callback for <Future at 0x7fac21f4df40 state=finished returned NoneType>
Traceback (most recent call last):
  File "/usr/lib/python3.8/concurrent/futures/_base.py", line 328, in _invoke_callbacks
    callback(self)
  File "/home/glima/Electrical-Behaviour-Prediction/SimulationManager/src/ExperimentManager.py", line 100, in <lambda>
    f.add_done_callback(lambda fut, i=idx: self.__callback(fut, i))
  File "/home/glima/Electrical-Behaviour-Prediction/SimulationManager/src/ExperimentManager.py", line 110, in __callback
    self.__completed.append(tmp_df)
  File "/home/glima/.local/lib/python3.8/site-packages/pandas/core/generic.py", line 5989, in __getattr__
    return object.__getattribute__(self, name)
AttributeError: 'DataFrame' object has no attribute 'append'
INFO:root:9 ended
ERROR:concurrent.futures:exception calling callback for <Future at 0x7fac21ed7190 state=finished returned NoneType>
Traceback (most recent call last):
  File "/usr/lib/python3.8/concurrent/futures/_base.py", line 328, in _invoke_callbacks
    callback(self)
  File "/home/glima/Electrical-Behaviour-Prediction/SimulationManager/src/ExperimentManager.py", line 100, in <lambda>
    f.add_done_callback(lambda fut, i=idx: self.__callback(fut, i))
  File "/home/glima/Electrical-Behaviour-Prediction/SimulationManager/src/ExperimentManager.py", line 110, in __callback
    self.__completed.append(tmp_df)
  File "/home/glima/.local/lib/python3.8/site-packages/pandas/core/generic.py", line 5989, in __getattr__
    return object.__getattribute__(self, name)
AttributeError: 'DataFrame' object has no attribute 'append'
INFO:root:6 ended
ERROR:concurrent.futures:exception calling callback for <Future at 0x7fac21f4ddf0 state=finished returned NoneType>
Traceback (most recent call last):
  File "/usr/lib/python3.8/concurrent/futures/_base.py", line 328, in _invoke_callbacks
    callback(self)
  File "/home/glima/Electrical-Behaviour-Prediction/SimulationManager/src/ExperimentManager.py", line 100, in <lambda>
    f.add_done_callback(lambda fut, i=idx: self.__callback(fut, i))
  File "/home/glima/Electrical-Behaviour-Prediction/SimulationManager/src/ExperimentManager.py", line 110, in __callback
    self.__completed.append(tmp_df)
  File "/home/glima/.local/lib/python3.8/site-packages/pandas/core/generic.py", line 5989, in __getattr__
    return object.__getattribute__(self, name)
AttributeError: 'DataFrame' object has no attribute 'append'
INFO:root:8 ended
ERROR:concurrent.futures:exception calling callback for <Future at 0x7fac21f4de80 state=finished returned NoneType>
Traceback (most recent call last):
  File "/usr/lib/python3.8/concurrent/futures/_base.py", line 328, in _invoke_callbacks
    callback(self)
  File "/home/glima/Electrical-Behaviour-Prediction/SimulationManager/src/ExperimentManager.py", line 100, in <lambda>
    f.add_done_callback(lambda fut, i=idx: self.__callback(fut, i))
  File "/home/glima/Electrical-Behaviour-Prediction/SimulationManager/src/ExperimentManager.py", line 110, in __callback
    self.__completed.append(tmp_df)
  File "/home/glima/.local/lib/python3.8/site-packages/pandas/core/generic.py", line 5989, in __getattr__
    return object.__getattribute__(self, name)
AttributeError: 'DataFrame' object has no attribute 'append'
INFO:root:10 ended
ERROR:concurrent.futures:exception calling callback for <Future at 0x7fac21f4d220 state=finished returned NoneType>
Traceback (most recent call last):
  File "/usr/lib/python3.8/concurrent/futures/_base.py", line 328, in _invoke_callbacks
    callback(self)
  File "/home/glima/Electrical-Behaviour-Prediction/SimulationManager/src/ExperimentManager.py", line 100, in <lambda>
    f.add_done_callback(lambda fut, i=idx: self.__callback(fut, i))
  File "/home/glima/Electrical-Behaviour-Prediction/SimulationManager/src/ExperimentManager.py", line 110, in __callback
    self.__completed.append(tmp_df)
  File "/home/glima/.local/lib/python3.8/site-packages/pandas/core/generic.py", line 5989, in __getattr__
    return object.__getattribute__(self, name)
AttributeError: 'DataFrame' object has no attribute 'append'
INFO:root:11 ended
ERROR:concurrent.futures:exception calling callback for <Future at 0x7fac21ed7400 state=finished returned NoneType>
Traceback (most recent call last):
  File "/usr/lib/python3.8/concurrent/futures/_base.py", line 328, in _invoke_callbacks
    callback(self)
  File "/home/glima/Electrical-Behaviour-Prediction/SimulationManager/src/ExperimentManager.py", line 100, in <lambda>
    f.add_done_callback(lambda fut, i=idx: self.__callback(fut, i))
  File "/home/glima/Electrical-Behaviour-Prediction/SimulationManager/src/ExperimentManager.py", line 110, in __callback
    self.__completed.append(tmp_df)
  File "/home/glima/.local/lib/python3.8/site-packages/pandas/core/generic.py", line 5989, in __getattr__
    return object.__getattribute__(self, name)
AttributeError: 'DataFrame' object has no attribute 'append'
INFO:root:12 ended
ERROR:concurrent.futures:exception calling callback for <Future at 0x7fac21ed75e0 state=finished returned NoneType>
Traceback (most recent call last):
  File "/usr/lib/python3.8/concurrent/futures/_base.py", line 328, in _invoke_callbacks
    callback(self)
  File "/home/glima/Electrical-Behaviour-Prediction/SimulationManager/src/ExperimentManager.py", line 100, in <lambda>
    f.add_done_callback(lambda fut, i=idx: self.__callback(fut, i))
  File "/home/glima/Electrical-Behaviour-Prediction/SimulationManager/src/ExperimentManager.py", line 110, in __callback
    self.__completed.append(tmp_df)
  File "/home/glima/.local/lib/python3.8/site-packages/pandas/core/generic.py", line 5989, in __getattr__
    return object.__getattribute__(self, name)
AttributeError: 'DataFrame' object has no attribute 'append'
INFO:root:13 ended
ERROR:concurrent.futures:exception calling callback for <Future at 0x7fac21ed7730 state=finished returned NoneType>
Traceback (most recent call last):
  File "/usr/lib/python3.8/concurrent/futures/_base.py", line 328, in _invoke_callbacks
    callback(self)
  File "/home/glima/Electrical-Behaviour-Prediction/SimulationManager/src/ExperimentManager.py", line 100, in <lambda>
    f.add_done_callback(lambda fut, i=idx: self.__callback(fut, i))
  File "/home/glima/Electrical-Behaviour-Prediction/SimulationManager/src/ExperimentManager.py", line 110, in __callback
    self.__completed.append(tmp_df)
  File "/home/glima/.local/lib/python3.8/site-packages/pandas/core/generic.py", line 5989, in __getattr__
    return object.__getattribute__(self, name)
AttributeError: 'DataFrame' object has no attribute 'append'
INFO:root:14 ended
ERROR:concurrent.futures:exception calling callback for <Future at 0x7fac21ed7880 state=finished returned NoneType>
Traceback (most recent call last):
  File "/usr/lib/python3.8/concurrent/futures/_base.py", line 328, in _invoke_callbacks
    callback(self)
  File "/home/glima/Electrical-Behaviour-Prediction/SimulationManager/src/ExperimentManager.py", line 100, in <lambda>
    f.add_done_callback(lambda fut, i=idx: self.__callback(fut, i))
  File "/home/glima/Electrical-Behaviour-Prediction/SimulationManager/src/ExperimentManager.py", line 110, in __callback
    self.__completed.append(tmp_df)
  File "/home/glima/.local/lib/python3.8/site-packages/pandas/core/generic.py", line 5989, in __getattr__
    return object.__getattribute__(self, name)
AttributeError: 'DataFrame' object has no attribute 'append'
INFO:root:15 ended
ERROR:concurrent.futures:exception calling callback for <Future at 0x7fac21ed79d0 state=finished returned NoneType>
Traceback (most recent call last):
  File "/usr/lib/python3.8/concurrent/futures/_base.py", line 328, in _invoke_callbacks
    callback(self)
  File "/home/glima/Electrical-Behaviour-Prediction/SimulationManager/src/ExperimentManager.py", line 100, in <lambda>
    f.add_done_callback(lambda fut, i=idx: self.__callback(fut, i))
  File "/home/glima/Electrical-Behaviour-Prediction/SimulationManager/src/ExperimentManager.py", line 110, in __callback
    self.__completed.append(tmp_df)
  File "/home/glima/.local/lib/python3.8/site-packages/pandas/core/generic.py", line 5989, in __getattr__
    return object.__getattribute__(self, name)
AttributeError: 'DataFrame' object has no attribute 'append'
INFO:root:17 ended
ERROR:concurrent.futures:exception calling callback for <Future at 0x7fac21ed7c70 state=finished returned NoneType>
Traceback (most recent call last):
  File "/usr/lib/python3.8/concurrent/futures/_base.py", line 328, in _invoke_callbacks
    callback(self)
  File "/home/glima/Electrical-Behaviour-Prediction/SimulationManager/src/ExperimentManager.py", line 100, in <lambda>
    f.add_done_callback(lambda fut, i=idx: self.__callback(fut, i))
  File "/home/glima/Electrical-Behaviour-Prediction/SimulationManager/src/ExperimentManager.py", line 110, in __callback
    self.__completed.append(tmp_df)
  File "/home/glima/.local/lib/python3.8/site-packages/pandas/core/generic.py", line 5989, in __getattr__
    return object.__getattribute__(self, name)
AttributeError: 'DataFrame' object has no attribute 'append'
INFO:root:16 ended
ERROR:concurrent.futures:exception calling callback for <Future at 0x7fac21ed7b20 state=finished returned NoneType>
Traceback (most recent call last):
  File "/usr/lib/python3.8/concurrent/futures/_base.py", line 328, in _invoke_callbacks
    callback(self)
  File "/home/glima/Electrical-Behaviour-Prediction/SimulationManager/src/ExperimentManager.py", line 100, in <lambda>
    f.add_done_callback(lambda fut, i=idx: self.__callback(fut, i))
  File "/home/glima/Electrical-Behaviour-Prediction/SimulationManager/src/ExperimentManager.py", line 110, in __callback
    self.__completed.append(tmp_df)
  File "/home/glima/.local/lib/python3.8/site-packages/pandas/core/generic.py", line 5989, in __getattr__
    return object.__getattribute__(self, name)
AttributeError: 'DataFrame' object has no attribute 'append'
INFO:root:21 ended
ERROR:concurrent.futures:exception calling callback for <Future at 0x7fac21edd160 state=finished returned NoneType>
Traceback (most recent call last):
  File "/usr/lib/python3.8/concurrent/futures/_base.py", line 328, in _invoke_callbacks
    callback(self)
  File "/home/glima/Electrical-Behaviour-Prediction/SimulationManager/src/ExperimentManager.py", line 100, in <lambda>
    f.add_done_callback(lambda fut, i=idx: self.__callback(fut, i))
  File "/home/glima/Electrical-Behaviour-Prediction/SimulationManager/src/ExperimentManager.py", line 110, in __callback
    self.__completed.append(tmp_df)
  File "/home/glima/.local/lib/python3.8/site-packages/pandas/core/generic.py", line 5989, in __getattr__
    return object.__getattribute__(self, name)
AttributeError: 'DataFrame' object has no attribute 'append'
INFO:root:23 ended
ERROR:concurrent.futures:exception calling callback for <Future at 0x7fac21edd4f0 state=finished returned NoneType>
Traceback (most recent call last):
  File "/usr/lib/python3.8/concurrent/futures/_base.py", line 328, in _invoke_callbacks
    callback(self)
  File "/home/glima/Electrical-Behaviour-Prediction/SimulationManager/src/ExperimentManager.py", line 100, in <lambda>
    f.add_done_callback(lambda fut, i=idx: self.__callback(fut, i))
  File "/home/glima/Electrical-Behaviour-Prediction/SimulationManager/src/ExperimentManager.py", line 110, in __callback
    self.__completed.append(tmp_df)
  File "/home/glima/.local/lib/python3.8/site-packages/pandas/core/generic.py", line 5989, in __getattr__
    return object.__getattribute__(self, name)
AttributeError: 'DataFrame' object has no attribute 'append'
INFO:root:18 ended
ERROR:concurrent.futures:exception calling callback for <Future at 0x7fac21ed7dc0 state=finished returned NoneType>
Traceback (most recent call last):
  File "/usr/lib/python3.8/concurrent/futures/_base.py", line 328, in _invoke_callbacks
    callback(self)
  File "/home/glima/Electrical-Behaviour-Prediction/SimulationManager/src/ExperimentManager.py", line 100, in <lambda>
    f.add_done_callback(lambda fut, i=idx: self.__callback(fut, i))
  File "/home/glima/Electrical-Behaviour-Prediction/SimulationManager/src/ExperimentManager.py", line 110, in __callback
    self.__completed.append(tmp_df)
  File "/home/glima/.local/lib/python3.8/site-packages/pandas/core/generic.py", line 5989, in __getattr__
    return object.__getattribute__(self, name)
AttributeError: 'DataFrame' object has no attribute 'append'
INFO:root:22 ended
ERROR:concurrent.futures:exception calling callback for <Future at 0x7fac21edd0d0 state=finished returned NoneType>
Traceback (most recent call last):
  File "/usr/lib/python3.8/concurrent/futures/_base.py", line 328, in _invoke_callbacks
    callback(self)
  File "/home/glima/Electrical-Behaviour-Prediction/SimulationManager/src/ExperimentManager.py", line 100, in <lambda>
    f.add_done_callback(lambda fut, i=idx: self.__callback(fut, i))
  File "/home/glima/Electrical-Behaviour-Prediction/SimulationManager/src/ExperimentManager.py", line 110, in __callback
    self.__completed.append(tmp_df)
  File "/home/glima/.local/lib/python3.8/site-packages/pandas/core/generic.py", line 5989, in __getattr__
    return object.__getattribute__(self, name)
AttributeError: 'DataFrame' object has no attribute 'append'
INFO:root:20 ended
ERROR:concurrent.futures:exception calling callback for <Future at 0x7fac21ed7e50 state=finished returned NoneType>
Traceback (most recent call last):
  File "/usr/lib/python3.8/concurrent/futures/_base.py", line 328, in _invoke_callbacks
    callback(self)
  File "/home/glima/Electrical-Behaviour-Prediction/SimulationManager/src/ExperimentManager.py", line 100, in <lambda>
    f.add_done_callback(lambda fut, i=idx: self.__callback(fut, i))
  File "/home/glima/Electrical-Behaviour-Prediction/SimulationManager/src/ExperimentManager.py", line 110, in __callback
    self.__completed.append(tmp_df)
  File "/home/glima/.local/lib/python3.8/site-packages/pandas/core/generic.py", line 5989, in __getattr__
    return object.__getattribute__(self, name)
AttributeError: 'DataFrame' object has no attribute 'append'
INFO:root:19 ended
ERROR:concurrent.futures:exception calling callback for <Future at 0x7fac21ed7f10 state=finished returned NoneType>
Traceback (most recent call last):
  File "/usr/lib/python3.8/concurrent/futures/_base.py", line 328, in _invoke_callbacks
    callback(self)
  File "/home/glima/Electrical-Behaviour-Prediction/SimulationManager/src/ExperimentManager.py", line 100, in <lambda>
    f.add_done_callback(lambda fut, i=idx: self.__callback(fut, i))
  File "/home/glima/Electrical-Behaviour-Prediction/SimulationManager/src/ExperimentManager.py", line 110, in __callback
    self.__completed.append(tmp_df)
  File "/home/glima/.local/lib/python3.8/site-packages/pandas/core/generic.py", line 5989, in __getattr__
    return object.__getattribute__(self, name)
AttributeError: 'DataFrame' object has no attribute 'append'
INFO:root:24 ended
ERROR:concurrent.futures:exception calling callback for <Future at 0x7fac21f4d7c0 state=finished returned NoneType>
Traceback (most recent call last):
  File "/usr/lib/python3.8/concurrent/futures/_base.py", line 328, in _invoke_callbacks
    callback(self)
  File "/home/glima/Electrical-Behaviour-Prediction/SimulationManager/src/ExperimentManager.py", line 100, in <lambda>
    f.add_done_callback(lambda fut, i=idx: self.__callback(fut, i))
  File "/home/glima/Electrical-Behaviour-Prediction/SimulationManager/src/ExperimentManager.py", line 110, in __callback
    self.__completed.append(tmp_df)
  File "/home/glima/.local/lib/python3.8/site-packages/pandas/core/generic.py", line 5989, in __getattr__
    return object.__getattribute__(self, name)
AttributeError: 'DataFrame' object has no attribute 'append'
INFO:root:26 ended
ERROR:concurrent.futures:exception calling callback for <Future at 0x7fac21edd8e0 state=finished returned NoneType>
Traceback (most recent call last):
  File "/usr/lib/python3.8/concurrent/futures/_base.py", line 328, in _invoke_callbacks
    callback(self)
  File "/home/glima/Electrical-Behaviour-Prediction/SimulationManager/src/ExperimentManager.py", line 100, in <lambda>
    f.add_done_callback(lambda fut, i=idx: self.__callback(fut, i))
  File "/home/glima/Electrical-Behaviour-Prediction/SimulationManager/src/ExperimentManager.py", line 110, in __callback
    self.__completed.append(tmp_df)
  File "/home/glima/.local/lib/python3.8/site-packages/pandas/core/generic.py", line 5989, in __getattr__
    return object.__getattribute__(self, name)
AttributeError: 'DataFrame' object has no attribute 'append'
INFO:root:29 ended
ERROR:concurrent.futures:exception calling callback for <Future at 0x7fac21eddd30 state=finished returned NoneType>
Traceback (most recent call last):
  File "/usr/lib/python3.8/concurrent/futures/_base.py", line 328, in _invoke_callbacks
    callback(self)
  File "/home/glima/Electrical-Behaviour-Prediction/SimulationManager/src/ExperimentManager.py", line 100, in <lambda>
    f.add_done_callback(lambda fut, i=idx: self.__callback(fut, i))
  File "/home/glima/Electrical-Behaviour-Prediction/SimulationManager/src/ExperimentManager.py", line 110, in __callback
    self.__completed.append(tmp_df)
  File "/home/glima/.local/lib/python3.8/site-packages/pandas/core/generic.py", line 5989, in __getattr__
    return object.__getattribute__(self, name)
AttributeError: 'DataFrame' object has no attribute 'append'
INFO:root:28 ended
ERROR:concurrent.futures:exception calling callback for <Future at 0x7fac21eddbe0 state=finished returned NoneType>
Traceback (most recent call last):
  File "/usr/lib/python3.8/concurrent/futures/_base.py", line 328, in _invoke_callbacks
    callback(self)
  File "/home/glima/Electrical-Behaviour-Prediction/SimulationManager/src/ExperimentManager.py", line 100, in <lambda>
    f.add_done_callback(lambda fut, i=idx: self.__callback(fut, i))
  File "/home/glima/Electrical-Behaviour-Prediction/SimulationManager/src/ExperimentManager.py", line 110, in __callback
    self.__completed.append(tmp_df)
  File "/home/glima/.local/lib/python3.8/site-packages/pandas/core/generic.py", line 5989, in __getattr__
    return object.__getattribute__(self, name)
AttributeError: 'DataFrame' object has no attribute 'append'
INFO:root:25 ended
ERROR:concurrent.futures:exception calling callback for <Future at 0x7fac21edd730 state=finished returned NoneType>
Traceback (most recent call last):
  File "/usr/lib/python3.8/concurrent/futures/_base.py", line 328, in _invoke_callbacks
    callback(self)
  File "/home/glima/Electrical-Behaviour-Prediction/SimulationManager/src/ExperimentManager.py", line 100, in <lambda>
    f.add_done_callback(lambda fut, i=idx: self.__callback(fut, i))
  File "/home/glima/Electrical-Behaviour-Prediction/SimulationManager/src/ExperimentManager.py", line 110, in __callback
    self.__completed.append(tmp_df)
  File "/home/glima/.local/lib/python3.8/site-packages/pandas/core/generic.py", line 5989, in __getattr__
    return object.__getattribute__(self, name)
AttributeError: 'DataFrame' object has no attribute 'append'
INFO:root:27 ended
ERROR:concurrent.futures:exception calling callback for <Future at 0x7fac21edda90 state=finished returned NoneType>
Traceback (most recent call last):
  File "/usr/lib/python3.8/concurrent/futures/_base.py", line 328, in _invoke_callbacks
    callback(self)
  File "/home/glima/Electrical-Behaviour-Prediction/SimulationManager/src/ExperimentManager.py", line 100, in <lambda>
    f.add_done_callback(lambda fut, i=idx: self.__callback(fut, i))
  File "/home/glima/Electrical-Behaviour-Prediction/SimulationManager/src/ExperimentManager.py", line 110, in __callback
    self.__completed.append(tmp_df)
  File "/home/glima/.local/lib/python3.8/site-packages/pandas/core/generic.py", line 5989, in __getattr__
    return object.__getattribute__(self, name)
AttributeError: 'DataFrame' object has no attribute 'append'
INFO:root:30 ended
ERROR:concurrent.futures:exception calling callback for <Future at 0x7fac21edde80 state=finished returned NoneType>
Traceback (most recent call last):
  File "/usr/lib/python3.8/concurrent/futures/_base.py", line 328, in _invoke_callbacks
    callback(self)
  File "/home/glima/Electrical-Behaviour-Prediction/SimulationManager/src/ExperimentManager.py", line 100, in <lambda>
    f.add_done_callback(lambda fut, i=idx: self.__callback(fut, i))
  File "/home/glima/Electrical-Behaviour-Prediction/SimulationManager/src/ExperimentManager.py", line 110, in __callback
    self.__completed.append(tmp_df)
  File "/home/glima/.local/lib/python3.8/site-packages/pandas/core/generic.py", line 5989, in __getattr__
    return object.__getattribute__(self, name)
AttributeError: 'DataFrame' object has no attribute 'append'
INFO:root:34 ended
ERROR:concurrent.futures:exception calling callback for <Future at 0x7fac21ee7400 state=finished returned NoneType>
Traceback (most recent call last):
  File "/usr/lib/python3.8/concurrent/futures/_base.py", line 328, in _invoke_callbacks
    callback(self)
  File "/home/glima/Electrical-Behaviour-Prediction/SimulationManager/src/ExperimentManager.py", line 100, in <lambda>
    f.add_done_callback(lambda fut, i=idx: self.__callback(fut, i))
  File "/home/glima/Electrical-Behaviour-Prediction/SimulationManager/src/ExperimentManager.py", line 110, in __callback
    self.__completed.append(tmp_df)
  File "/home/glima/.local/lib/python3.8/site-packages/pandas/core/generic.py", line 5989, in __getattr__
    return object.__getattribute__(self, name)
AttributeError: 'DataFrame' object has no attribute 'append'
INFO:root:32 ended
ERROR:concurrent.futures:exception calling callback for <Future at 0x7fac21eddf10 state=finished returned NoneType>
Traceback (most recent call last):
  File "/usr/lib/python3.8/concurrent/futures/_base.py", line 328, in _invoke_callbacks
    callback(self)
  File "/home/glima/Electrical-Behaviour-Prediction/SimulationManager/src/ExperimentManager.py", line 100, in <lambda>
    f.add_done_callback(lambda fut, i=idx: self.__callback(fut, i))
  File "/home/glima/Electrical-Behaviour-Prediction/SimulationManager/src/ExperimentManager.py", line 110, in __callback
    self.__completed.append(tmp_df)
  File "/home/glima/.local/lib/python3.8/site-packages/pandas/core/generic.py", line 5989, in __getattr__
    return object.__getattribute__(self, name)
AttributeError: 'DataFrame' object has no attribute 'append'
INFO:root:31 ended
ERROR:concurrent.futures:exception calling callback for <Future at 0x7fac21eddfd0 state=finished returned NoneType>
Traceback (most recent call last):
  File "/usr/lib/python3.8/concurrent/futures/_base.py", line 328, in _invoke_callbacks
    callback(self)
  File "/home/glima/Electrical-Behaviour-Prediction/SimulationManager/src/ExperimentManager.py", line 100, in <lambda>
    f.add_done_callback(lambda fut, i=idx: self.__callback(fut, i))
  File "/home/glima/Electrical-Behaviour-Prediction/SimulationManager/src/ExperimentManager.py", line 110, in __callback
    self.__completed.append(tmp_df)
  File "/home/glima/.local/lib/python3.8/site-packages/pandas/core/generic.py", line 5989, in __getattr__
    return object.__getattribute__(self, name)
AttributeError: 'DataFrame' object has no attribute 'append'
INFO:root:33 ended
ERROR:concurrent.futures:exception calling callback for <Future at 0x7fac21ee7220 state=finished returned NoneType>
Traceback (most recent call last):
  File "/usr/lib/python3.8/concurrent/futures/_base.py", line 328, in _invoke_callbacks
    callback(self)
  File "/home/glima/Electrical-Behaviour-Prediction/SimulationManager/src/ExperimentManager.py", line 100, in <lambda>
    f.add_done_callback(lambda fut, i=idx: self.__callback(fut, i))
  File "/home/glima/Electrical-Behaviour-Prediction/SimulationManager/src/ExperimentManager.py", line 110, in __callback
    self.__completed.append(tmp_df)
  File "/home/glima/.local/lib/python3.8/site-packages/pandas/core/generic.py", line 5989, in __getattr__
    return object.__getattribute__(self, name)
AttributeError: 'DataFrame' object has no attribute 'append'
INFO:root:35 ended
ERROR:concurrent.futures:exception calling callback for <Future at 0x7fac21ee7550 state=finished returned NoneType>
Traceback (most recent call last):
  File "/usr/lib/python3.8/concurrent/futures/_base.py", line 328, in _invoke_callbacks
    callback(self)
  File "/home/glima/Electrical-Behaviour-Prediction/SimulationManager/src/ExperimentManager.py", line 100, in <lambda>
    f.add_done_callback(lambda fut, i=idx: self.__callback(fut, i))
  File "/home/glima/Electrical-Behaviour-Prediction/SimulationManager/src/ExperimentManager.py", line 110, in __callback
    self.__completed.append(tmp_df)
  File "/home/glima/.local/lib/python3.8/site-packages/pandas/core/generic.py", line 5989, in __getattr__
    return object.__getattribute__(self, name)
AttributeError: 'DataFrame' object has no attribute 'append'
INFO:root:36 ended
ERROR:concurrent.futures:exception calling callback for <Future at 0x7fac21ee76a0 state=finished returned NoneType>
Traceback (most recent call last):
  File "/usr/lib/python3.8/concurrent/futures/_base.py", line 328, in _invoke_callbacks
    callback(self)
  File "/home/glima/Electrical-Behaviour-Prediction/SimulationManager/src/ExperimentManager.py", line 100, in <lambda>
    f.add_done_callback(lambda fut, i=idx: self.__callback(fut, i))
  File "/home/glima/Electrical-Behaviour-Prediction/SimulationManager/src/ExperimentManager.py", line 110, in __callback
    self.__completed.append(tmp_df)
  File "/home/glima/.local/lib/python3.8/site-packages/pandas/core/generic.py", line 5989, in __getattr__
    return object.__getattribute__(self, name)
AttributeError: 'DataFrame' object has no attribute 'append'
INFO:root:40 ended
ERROR:concurrent.futures:exception calling callback for <Future at 0x7fac21ee7be0 state=finished returned NoneType>
Traceback (most recent call last):
  File "/usr/lib/python3.8/concurrent/futures/_base.py", line 328, in _invoke_callbacks
    callback(self)
  File "/home/glima/Electrical-Behaviour-Prediction/SimulationManager/src/ExperimentManager.py", line 100, in <lambda>
    f.add_done_callback(lambda fut, i=idx: self.__callback(fut, i))
  File "/home/glima/Electrical-Behaviour-Prediction/SimulationManager/src/ExperimentManager.py", line 110, in __callback
    self.__completed.append(tmp_df)
  File "/home/glima/.local/lib/python3.8/site-packages/pandas/core/generic.py", line 5989, in __getattr__
    return object.__getattribute__(self, name)
AttributeError: 'DataFrame' object has no attribute 'append'
INFO:root:39 ended
ERROR:concurrent.futures:exception calling callback for <Future at 0x7fac21ee7a90 state=finished returned NoneType>
Traceback (most recent call last):
  File "/usr/lib/python3.8/concurrent/futures/_base.py", line 328, in _invoke_callbacks
    callback(self)
  File "/home/glima/Electrical-Behaviour-Prediction/SimulationManager/src/ExperimentManager.py", line 100, in <lambda>
    f.add_done_callback(lambda fut, i=idx: self.__callback(fut, i))
  File "/home/glima/Electrical-Behaviour-Prediction/SimulationManager/src/ExperimentManager.py", line 110, in __callback
    self.__completed.append(tmp_df)
  File "/home/glima/.local/lib/python3.8/site-packages/pandas/core/generic.py", line 5989, in __getattr__
    return object.__getattribute__(self, name)
AttributeError: 'DataFrame' object has no attribute 'append'
INFO:root:38 ended
ERROR:concurrent.futures:exception calling callback for <Future at 0x7fac21ee7940 state=finished returned NoneType>
Traceback (most recent call last):
  File "/usr/lib/python3.8/concurrent/futures/_base.py", line 328, in _invoke_callbacks
    callback(self)
  File "/home/glima/Electrical-Behaviour-Prediction/SimulationManager/src/ExperimentManager.py", line 100, in <lambda>
    f.add_done_callback(lambda fut, i=idx: self.__callback(fut, i))
  File "/home/glima/Electrical-Behaviour-Prediction/SimulationManager/src/ExperimentManager.py", line 110, in __callback
    self.__completed.append(tmp_df)
  File "/home/glima/.local/lib/python3.8/site-packages/pandas/core/generic.py", line 5989, in __getattr__
    return object.__getattribute__(self, name)
AttributeError: 'DataFrame' object has no attribute 'append'
INFO:root:37 ended
ERROR:concurrent.futures:exception calling callback for <Future at 0x7fac21ee77f0 state=finished returned NoneType>
Traceback (most recent call last):
  File "/usr/lib/python3.8/concurrent/futures/_base.py", line 328, in _invoke_callbacks
    callback(self)
  File "/home/glima/Electrical-Behaviour-Prediction/SimulationManager/src/ExperimentManager.py", line 100, in <lambda>
    f.add_done_callback(lambda fut, i=idx: self.__callback(fut, i))
  File "/home/glima/Electrical-Behaviour-Prediction/SimulationManager/src/ExperimentManager.py", line 110, in __callback
    self.__completed.append(tmp_df)
  File "/home/glima/.local/lib/python3.8/site-packages/pandas/core/generic.py", line 5989, in __getattr__
    return object.__getattribute__(self, name)
AttributeError: 'DataFrame' object has no attribute 'append'
INFO:root:41 ended
ERROR:concurrent.futures:exception calling callback for <Future at 0x7fac21ee7d30 state=finished returned NoneType>
Traceback (most recent call last):
  File "/usr/lib/python3.8/concurrent/futures/_base.py", line 328, in _invoke_callbacks
    callback(self)
  File "/home/glima/Electrical-Behaviour-Prediction/SimulationManager/src/ExperimentManager.py", line 100, in <lambda>
    f.add_done_callback(lambda fut, i=idx: self.__callback(fut, i))
  File "/home/glima/Electrical-Behaviour-Prediction/SimulationManager/src/ExperimentManager.py", line 110, in __callback
    self.__completed.append(tmp_df)
  File "/home/glima/.local/lib/python3.8/site-packages/pandas/core/generic.py", line 5989, in __getattr__
    return object.__getattribute__(self, name)
AttributeError: 'DataFrame' object has no attribute 'append'
INFO:root:42 ended
ERROR:concurrent.futures:exception calling callback for <Future at 0x7fac21ee7e80 state=finished returned NoneType>
Traceback (most recent call last):
  File "/usr/lib/python3.8/concurrent/futures/_base.py", line 328, in _invoke_callbacks
    callback(self)
  File "/home/glima/Electrical-Behaviour-Prediction/SimulationManager/src/ExperimentManager.py", line 100, in <lambda>
    f.add_done_callback(lambda fut, i=idx: self.__callback(fut, i))
  File "/home/glima/Electrical-Behaviour-Prediction/SimulationManager/src/ExperimentManager.py", line 110, in __callback
    self.__completed.append(tmp_df)
  File "/home/glima/.local/lib/python3.8/site-packages/pandas/core/generic.py", line 5989, in __getattr__
    return object.__getattribute__(self, name)
AttributeError: 'DataFrame' object has no attribute 'append'
INFO:root:45 ended
ERROR:concurrent.futures:exception calling callback for <Future at 0x7fac21ef0220 state=finished returned NoneType>
Traceback (most recent call last):
  File "/usr/lib/python3.8/concurrent/futures/_base.py", line 328, in _invoke_callbacks
    callback(self)
  File "/home/glima/Electrical-Behaviour-Prediction/SimulationManager/src/ExperimentManager.py", line 100, in <lambda>
    f.add_done_callback(lambda fut, i=idx: self.__callback(fut, i))
  File "/home/glima/Electrical-Behaviour-Prediction/SimulationManager/src/ExperimentManager.py", line 110, in __callback
    self.__completed.append(tmp_df)
  File "/home/glima/.local/lib/python3.8/site-packages/pandas/core/generic.py", line 5989, in __getattr__
    return object.__getattribute__(self, name)
AttributeError: 'DataFrame' object has no attribute 'append'
INFO:root:43 ended
ERROR:concurrent.futures:exception calling callback for <Future at 0x7fac21ee7fd0 state=finished returned NoneType>
Traceback (most recent call last):
  File "/usr/lib/python3.8/concurrent/futures/_base.py", line 328, in _invoke_callbacks
    callback(self)
  File "/home/glima/Electrical-Behaviour-Prediction/SimulationManager/src/ExperimentManager.py", line 100, in <lambda>
    f.add_done_callback(lambda fut, i=idx: self.__callback(fut, i))
  File "/home/glima/Electrical-Behaviour-Prediction/SimulationManager/src/ExperimentManager.py", line 110, in __callback
    self.__completed.append(tmp_df)
  File "/home/glima/.local/lib/python3.8/site-packages/pandas/core/generic.py", line 5989, in __getattr__
    return object.__getattribute__(self, name)
AttributeError: 'DataFrame' object has no attribute 'append'
INFO:root:44 ended
ERROR:concurrent.futures:exception calling callback for <Future at 0x7fac21ee7f10 state=finished returned NoneType>
Traceback (most recent call last):
  File "/usr/lib/python3.8/concurrent/futures/_base.py", line 328, in _invoke_callbacks
    callback(self)
  File "/home/glima/Electrical-Behaviour-Prediction/SimulationManager/src/ExperimentManager.py", line 100, in <lambda>
    f.add_done_callback(lambda fut, i=idx: self.__callback(fut, i))
  File "/home/glima/Electrical-Behaviour-Prediction/SimulationManager/src/ExperimentManager.py", line 110, in __callback
    self.__completed.append(tmp_df)
  File "/home/glima/.local/lib/python3.8/site-packages/pandas/core/generic.py", line 5989, in __getattr__
    return object.__getattribute__(self, name)
AttributeError: 'DataFrame' object has no attribute 'append'
INFO:root:47 ended
ERROR:concurrent.futures:exception calling callback for <Future at 0x7fac21ef0550 state=finished returned NoneType>
Traceback (most recent call last):
  File "/usr/lib/python3.8/concurrent/futures/_base.py", line 328, in _invoke_callbacks
    callback(self)
  File "/home/glima/Electrical-Behaviour-Prediction/SimulationManager/src/ExperimentManager.py", line 100, in <lambda>
    f.add_done_callback(lambda fut, i=idx: self.__callback(fut, i))
  File "/home/glima/Electrical-Behaviour-Prediction/SimulationManager/src/ExperimentManager.py", line 110, in __callback
    self.__completed.append(tmp_df)
  File "/home/glima/.local/lib/python3.8/site-packages/pandas/core/generic.py", line 5989, in __getattr__
    return object.__getattribute__(self, name)
AttributeError: 'DataFrame' object has no attribute 'append'
INFO:root:46 ended
ERROR:concurrent.futures:exception calling callback for <Future at 0x7fac21ef0400 state=finished returned NoneType>
Traceback (most recent call last):
  File "/usr/lib/python3.8/concurrent/futures/_base.py", line 328, in _invoke_callbacks
    callback(self)
  File "/home/glima/Electrical-Behaviour-Prediction/SimulationManager/src/ExperimentManager.py", line 100, in <lambda>
    f.add_done_callback(lambda fut, i=idx: self.__callback(fut, i))
  File "/home/glima/Electrical-Behaviour-Prediction/SimulationManager/src/ExperimentManager.py", line 110, in __callback
    self.__completed.append(tmp_df)
  File "/home/glima/.local/lib/python3.8/site-packages/pandas/core/generic.py", line 5989, in __getattr__
    return object.__getattribute__(self, name)
AttributeError: 'DataFrame' object has no attribute 'append'
INFO:root:48 ended
ERROR:concurrent.futures:exception calling callback for <Future at 0x7fac21ef06a0 state=finished returned NoneType>
Traceback (most recent call last):
  File "/usr/lib/python3.8/concurrent/futures/_base.py", line 328, in _invoke_callbacks
    callback(self)
  File "/home/glima/Electrical-Behaviour-Prediction/SimulationManager/src/ExperimentManager.py", line 100, in <lambda>
    f.add_done_callback(lambda fut, i=idx: self.__callback(fut, i))
  File "/home/glima/Electrical-Behaviour-Prediction/SimulationManager/src/ExperimentManager.py", line 110, in __callback
    self.__completed.append(tmp_df)
  File "/home/glima/.local/lib/python3.8/site-packages/pandas/core/generic.py", line 5989, in __getattr__
    return object.__getattribute__(self, name)
AttributeError: 'DataFrame' object has no attribute 'append'
INFO:root:49 ended
ERROR:concurrent.futures:exception calling callback for <Future at 0x7fac21ef07f0 state=finished returned NoneType>
Traceback (most recent call last):
  File "/usr/lib/python3.8/concurrent/futures/_base.py", line 328, in _invoke_callbacks
    callback(self)
  File "/home/glima/Electrical-Behaviour-Prediction/SimulationManager/src/ExperimentManager.py", line 100, in <lambda>
    f.add_done_callback(lambda fut, i=idx: self.__callback(fut, i))
  File "/home/glima/Electrical-Behaviour-Prediction/SimulationManager/src/ExperimentManager.py", line 110, in __callback
    self.__completed.append(tmp_df)
  File "/home/glima/.local/lib/python3.8/site-packages/pandas/core/generic.py", line 5989, in __getattr__
    return object.__getattribute__(self, name)
AttributeError: 'DataFrame' object has no attribute 'append'
INFO:root:50 ended
ERROR:concurrent.futures:exception calling callback for <Future at 0x7fac21ef0940 state=finished returned NoneType>
Traceback (most recent call last):
  File "/usr/lib/python3.8/concurrent/futures/_base.py", line 328, in _invoke_callbacks
    callback(self)
  File "/home/glima/Electrical-Behaviour-Prediction/SimulationManager/src/ExperimentManager.py", line 100, in <lambda>
    f.add_done_callback(lambda fut, i=idx: self.__callback(fut, i))
  File "/home/glima/Electrical-Behaviour-Prediction/SimulationManager/src/ExperimentManager.py", line 110, in __callback
    self.__completed.append(tmp_df)
  File "/home/glima/.local/lib/python3.8/site-packages/pandas/core/generic.py", line 5989, in __getattr__
    return object.__getattribute__(self, name)
AttributeError: 'DataFrame' object has no attribute 'append'
INFO:root:53 ended
ERROR:concurrent.futures:exception calling callback for <Future at 0x7fac21ef0cd0 state=finished returned NoneType>
Traceback (most recent call last):
  File "/usr/lib/python3.8/concurrent/futures/_base.py", line 328, in _invoke_callbacks
    callback(self)
  File "/home/glima/Electrical-Behaviour-Prediction/SimulationManager/src/ExperimentManager.py", line 100, in <lambda>
    f.add_done_callback(lambda fut, i=idx: self.__callback(fut, i))
  File "/home/glima/Electrical-Behaviour-Prediction/SimulationManager/src/ExperimentManager.py", line 110, in __callback
    self.__completed.append(tmp_df)
  File "/home/glima/.local/lib/python3.8/site-packages/pandas/core/generic.py", line 5989, in __getattr__
    return object.__getattribute__(self, name)
AttributeError: 'DataFrame' object has no attribute 'append'
INFO:root:52 ended
ERROR:concurrent.futures:exception calling callback for <Future at 0x7fac21edd9a0 state=finished returned NoneType>
Traceback (most recent call last):
  File "/usr/lib/python3.8/concurrent/futures/_base.py", line 328, in _invoke_callbacks
    callback(self)
  File "/home/glima/Electrical-Behaviour-Prediction/SimulationManager/src/ExperimentManager.py", line 100, in <lambda>
    f.add_done_callback(lambda fut, i=idx: self.__callback(fut, i))
  File "/home/glima/Electrical-Behaviour-Prediction/SimulationManager/src/ExperimentManager.py", line 110, in __callback
    self.__completed.append(tmp_df)
  File "/home/glima/.local/lib/python3.8/site-packages/pandas/core/generic.py", line 5989, in __getattr__
    return object.__getattribute__(self, name)
AttributeError: 'DataFrame' object has no attribute 'append'
INFO:root:51 ended
ERROR:concurrent.futures:exception calling callback for <Future at 0x7fac21ef0a90 state=finished returned NoneType>
Traceback (most recent call last):
  File "/usr/lib/python3.8/concurrent/futures/_base.py", line 328, in _invoke_callbacks
    callback(self)
  File "/home/glima/Electrical-Behaviour-Prediction/SimulationManager/src/ExperimentManager.py", line 100, in <lambda>
    f.add_done_callback(lambda fut, i=idx: self.__callback(fut, i))
  File "/home/glima/Electrical-Behaviour-Prediction/SimulationManager/src/ExperimentManager.py", line 110, in __callback
    self.__completed.append(tmp_df)
  File "/home/glima/.local/lib/python3.8/site-packages/pandas/core/generic.py", line 5989, in __getattr__
    return object.__getattribute__(self, name)
AttributeError: 'DataFrame' object has no attribute 'append'
INFO:root:54 ended
ERROR:concurrent.futures:exception calling callback for <Future at 0x7fac21ef0b20 state=finished returned NoneType>
Traceback (most recent call last):
  File "/usr/lib/python3.8/concurrent/futures/_base.py", line 328, in _invoke_callbacks
    callback(self)
  File "/home/glima/Electrical-Behaviour-Prediction/SimulationManager/src/ExperimentManager.py", line 100, in <lambda>
    f.add_done_callback(lambda fut, i=idx: self.__callback(fut, i))
  File "/home/glima/Electrical-Behaviour-Prediction/SimulationManager/src/ExperimentManager.py", line 110, in __callback
    self.__completed.append(tmp_df)
  File "/home/glima/.local/lib/python3.8/site-packages/pandas/core/generic.py", line 5989, in __getattr__
    return object.__getattribute__(self, name)
AttributeError: 'DataFrame' object has no attribute 'append'
INFO:root:55 ended
ERROR:concurrent.futures:exception calling callback for <Future at 0x7fac21ef0f70 state=finished returned NoneType>
Traceback (most recent call last):
  File "/usr/lib/python3.8/concurrent/futures/_base.py", line 328, in _invoke_callbacks
    callback(self)
  File "/home/glima/Electrical-Behaviour-Prediction/SimulationManager/src/ExperimentManager.py", line 100, in <lambda>
    f.add_done_callback(lambda fut, i=idx: self.__callback(fut, i))
  File "/home/glima/Electrical-Behaviour-Prediction/SimulationManager/src/ExperimentManager.py", line 110, in __callback
    self.__completed.append(tmp_df)
  File "/home/glima/.local/lib/python3.8/site-packages/pandas/core/generic.py", line 5989, in __getattr__
    return object.__getattribute__(self, name)
AttributeError: 'DataFrame' object has no attribute 'append'
INFO:root:58 ended
ERROR:concurrent.futures:exception calling callback for <Future at 0x7fac21ef6400 state=finished returned NoneType>
Traceback (most recent call last):
  File "/usr/lib/python3.8/concurrent/futures/_base.py", line 328, in _invoke_callbacks
    callback(self)
  File "/home/glima/Electrical-Behaviour-Prediction/SimulationManager/src/ExperimentManager.py", line 100, in <lambda>
    f.add_done_callback(lambda fut, i=idx: self.__callback(fut, i))
  File "/home/glima/Electrical-Behaviour-Prediction/SimulationManager/src/ExperimentManager.py", line 110, in __callback
    self.__completed.append(tmp_df)
  File "/home/glima/.local/lib/python3.8/site-packages/pandas/core/generic.py", line 5989, in __getattr__
    return object.__getattribute__(self, name)
AttributeError: 'DataFrame' object has no attribute 'append'
INFO:root:59 ended
ERROR:concurrent.futures:exception calling callback for <Future at 0x7fac21ef6550 state=finished returned NoneType>
Traceback (most recent call last):
  File "/usr/lib/python3.8/concurrent/futures/_base.py", line 328, in _invoke_callbacks
    callback(self)
  File "/home/glima/Electrical-Behaviour-Prediction/SimulationManager/src/ExperimentManager.py", line 100, in <lambda>
    f.add_done_callback(lambda fut, i=idx: self.__callback(fut, i))
  File "/home/glima/Electrical-Behaviour-Prediction/SimulationManager/src/ExperimentManager.py", line 110, in __callback
    self.__completed.append(tmp_df)
  File "/home/glima/.local/lib/python3.8/site-packages/pandas/core/generic.py", line 5989, in __getattr__
    return object.__getattribute__(self, name)
AttributeError: 'DataFrame' object has no attribute 'append'
INFO:root:56 ended
ERROR:concurrent.futures:exception calling callback for <Future at 0x7fac21ef0e50 state=finished returned NoneType>
Traceback (most recent call last):
  File "/usr/lib/python3.8/concurrent/futures/_base.py", line 328, in _invoke_callbacks
    callback(self)
  File "/home/glima/Electrical-Behaviour-Prediction/SimulationManager/src/ExperimentManager.py", line 100, in <lambda>
    f.add_done_callback(lambda fut, i=idx: self.__callback(fut, i))
  File "/home/glima/Electrical-Behaviour-Prediction/SimulationManager/src/ExperimentManager.py", line 110, in __callback
    self.__completed.append(tmp_df)
  File "/home/glima/.local/lib/python3.8/site-packages/pandas/core/generic.py", line 5989, in __getattr__
    return object.__getattribute__(self, name)
AttributeError: 'DataFrame' object has no attribute 'append'
INFO:root:57 ended
ERROR:concurrent.futures:exception calling callback for <Future at 0x7fac21ef6220 state=finished returned NoneType>
Traceback (most recent call last):
  File "/usr/lib/python3.8/concurrent/futures/_base.py", line 328, in _invoke_callbacks
    callback(self)
  File "/home/glima/Electrical-Behaviour-Prediction/SimulationManager/src/ExperimentManager.py", line 100, in <lambda>
    f.add_done_callback(lambda fut, i=idx: self.__callback(fut, i))
  File "/home/glima/Electrical-Behaviour-Prediction/SimulationManager/src/ExperimentManager.py", line 110, in __callback
    self.__completed.append(tmp_df)
  File "/home/glima/.local/lib/python3.8/site-packages/pandas/core/generic.py", line 5989, in __getattr__
    return object.__getattribute__(self, name)
AttributeError: 'DataFrame' object has no attribute 'append'
INFO:root:60 ended
ERROR:concurrent.futures:exception calling callback for <Future at 0x7fac21ef66a0 state=finished returned NoneType>
Traceback (most recent call last):
  File "/usr/lib/python3.8/concurrent/futures/_base.py", line 328, in _invoke_callbacks
    callback(self)
  File "/home/glima/Electrical-Behaviour-Prediction/SimulationManager/src/ExperimentManager.py", line 100, in <lambda>
    f.add_done_callback(lambda fut, i=idx: self.__callback(fut, i))
  File "/home/glima/Electrical-Behaviour-Prediction/SimulationManager/src/ExperimentManager.py", line 110, in __callback
    self.__completed.append(tmp_df)
  File "/home/glima/.local/lib/python3.8/site-packages/pandas/core/generic.py", line 5989, in __getattr__
    return object.__getattribute__(self, name)
AttributeError: 'DataFrame' object has no attribute 'append'
INFO:root:61 ended
ERROR:concurrent.futures:exception calling callback for <Future at 0x7fac21ef67f0 state=finished returned NoneType>
Traceback (most recent call last):
  File "/usr/lib/python3.8/concurrent/futures/_base.py", line 328, in _invoke_callbacks
    callback(self)
  File "/home/glima/Electrical-Behaviour-Prediction/SimulationManager/src/ExperimentManager.py", line 100, in <lambda>
    f.add_done_callback(lambda fut, i=idx: self.__callback(fut, i))
  File "/home/glima/Electrical-Behaviour-Prediction/SimulationManager/src/ExperimentManager.py", line 110, in __callback
    self.__completed.append(tmp_df)
  File "/home/glima/.local/lib/python3.8/site-packages/pandas/core/generic.py", line 5989, in __getattr__
    return object.__getattribute__(self, name)
AttributeError: 'DataFrame' object has no attribute 'append'
INFO:root:62 ended
ERROR:concurrent.futures:exception calling callback for <Future at 0x7fac21ef6940 state=finished returned NoneType>
Traceback (most recent call last):
  File "/usr/lib/python3.8/concurrent/futures/_base.py", line 328, in _invoke_callbacks
    callback(self)
  File "/home/glima/Electrical-Behaviour-Prediction/SimulationManager/src/ExperimentManager.py", line 100, in <lambda>
    f.add_done_callback(lambda fut, i=idx: self.__callback(fut, i))
  File "/home/glima/Electrical-Behaviour-Prediction/SimulationManager/src/ExperimentManager.py", line 110, in __callback
    self.__completed.append(tmp_df)
  File "/home/glima/.local/lib/python3.8/site-packages/pandas/core/generic.py", line 5989, in __getattr__
    return object.__getattribute__(self, name)
AttributeError: 'DataFrame' object has no attribute 'append'
INFO:root:65 ended
ERROR:concurrent.futures:exception calling callback for <Future at 0x7fac21ef6d30 state=finished returned NoneType>
Traceback (most recent call last):
  File "/usr/lib/python3.8/concurrent/futures/_base.py", line 328, in _invoke_callbacks
    callback(self)
  File "/home/glima/Electrical-Behaviour-Prediction/SimulationManager/src/ExperimentManager.py", line 100, in <lambda>
    f.add_done_callback(lambda fut, i=idx: self.__callback(fut, i))
  File "/home/glima/Electrical-Behaviour-Prediction/SimulationManager/src/ExperimentManager.py", line 110, in __callback
    self.__completed.append(tmp_df)
  File "/home/glima/.local/lib/python3.8/site-packages/pandas/core/generic.py", line 5989, in __getattr__
    return object.__getattribute__(self, name)
AttributeError: 'DataFrame' object has no attribute 'append'
INFO:root:63 ended
ERROR:concurrent.futures:exception calling callback for <Future at 0x7fac21ef6a90 state=finished returned NoneType>
Traceback (most recent call last):
  File "/usr/lib/python3.8/concurrent/futures/_base.py", line 328, in _invoke_callbacks
    callback(self)
  File "/home/glima/Electrical-Behaviour-Prediction/SimulationManager/src/ExperimentManager.py", line 100, in <lambda>
    f.add_done_callback(lambda fut, i=idx: self.__callback(fut, i))
  File "/home/glima/Electrical-Behaviour-Prediction/SimulationManager/src/ExperimentManager.py", line 110, in __callback
    self.__completed.append(tmp_df)
  File "/home/glima/.local/lib/python3.8/site-packages/pandas/core/generic.py", line 5989, in __getattr__
    return object.__getattribute__(self, name)
AttributeError: 'DataFrame' object has no attribute 'append'
INFO:root:64 ended
ERROR:concurrent.futures:exception calling callback for <Future at 0x7fac21ef6be0 state=finished returned NoneType>
Traceback (most recent call last):
  File "/usr/lib/python3.8/concurrent/futures/_base.py", line 328, in _invoke_callbacks
    callback(self)
  File "/home/glima/Electrical-Behaviour-Prediction/SimulationManager/src/ExperimentManager.py", line 100, in <lambda>
    f.add_done_callback(lambda fut, i=idx: self.__callback(fut, i))
  File "/home/glima/Electrical-Behaviour-Prediction/SimulationManager/src/ExperimentManager.py", line 110, in __callback
    self.__completed.append(tmp_df)
  File "/home/glima/.local/lib/python3.8/site-packages/pandas/core/generic.py", line 5989, in __getattr__
    return object.__getattribute__(self, name)
AttributeError: 'DataFrame' object has no attribute 'append'
INFO:root:66 ended
ERROR:concurrent.futures:exception calling callback for <Future at 0x7fac21ef6e80 state=finished returned NoneType>
Traceback (most recent call last):
  File "/usr/lib/python3.8/concurrent/futures/_base.py", line 328, in _invoke_callbacks
    callback(self)
  File "/home/glima/Electrical-Behaviour-Prediction/SimulationManager/src/ExperimentManager.py", line 100, in <lambda>
    f.add_done_callback(lambda fut, i=idx: self.__callback(fut, i))
  File "/home/glima/Electrical-Behaviour-Prediction/SimulationManager/src/ExperimentManager.py", line 110, in __callback
    self.__completed.append(tmp_df)
  File "/home/glima/.local/lib/python3.8/site-packages/pandas/core/generic.py", line 5989, in __getattr__
    return object.__getattribute__(self, name)
AttributeError: 'DataFrame' object has no attribute 'append'
INFO:root:67 ended
ERROR:concurrent.futures:exception calling callback for <Future at 0x7fac21ef6fd0 state=finished returned NoneType>
Traceback (most recent call last):
  File "/usr/lib/python3.8/concurrent/futures/_base.py", line 328, in _invoke_callbacks
    callback(self)
  File "/home/glima/Electrical-Behaviour-Prediction/SimulationManager/src/ExperimentManager.py", line 100, in <lambda>
    f.add_done_callback(lambda fut, i=idx: self.__callback(fut, i))
  File "/home/glima/Electrical-Behaviour-Prediction/SimulationManager/src/ExperimentManager.py", line 110, in __callback
    self.__completed.append(tmp_df)
  File "/home/glima/.local/lib/python3.8/site-packages/pandas/core/generic.py", line 5989, in __getattr__
    return object.__getattribute__(self, name)
AttributeError: 'DataFrame' object has no attribute 'append'
INFO:root:68 ended
ERROR:concurrent.futures:exception calling callback for <Future at 0x7fac21ef0b50 state=finished returned NoneType>
Traceback (most recent call last):
  File "/usr/lib/python3.8/concurrent/futures/_base.py", line 328, in _invoke_callbacks
    callback(self)
  File "/home/glima/Electrical-Behaviour-Prediction/SimulationManager/src/ExperimentManager.py", line 100, in <lambda>
    f.add_done_callback(lambda fut, i=idx: self.__callback(fut, i))
  File "/home/glima/Electrical-Behaviour-Prediction/SimulationManager/src/ExperimentManager.py", line 110, in __callback
    self.__completed.append(tmp_df)
  File "/home/glima/.local/lib/python3.8/site-packages/pandas/core/generic.py", line 5989, in __getattr__
    return object.__getattribute__(self, name)
AttributeError: 'DataFrame' object has no attribute 'append'
INFO:root:70 ended
ERROR:concurrent.futures:exception calling callback for <Future at 0x7fac21efd400 state=finished returned NoneType>
Traceback (most recent call last):
  File "/usr/lib/python3.8/concurrent/futures/_base.py", line 328, in _invoke_callbacks
    callback(self)
  File "/home/glima/Electrical-Behaviour-Prediction/SimulationManager/src/ExperimentManager.py", line 100, in <lambda>
    f.add_done_callback(lambda fut, i=idx: self.__callback(fut, i))
  File "/home/glima/Electrical-Behaviour-Prediction/SimulationManager/src/ExperimentManager.py", line 110, in __callback
    self.__completed.append(tmp_df)
  File "/home/glima/.local/lib/python3.8/site-packages/pandas/core/generic.py", line 5989, in __getattr__
    return object.__getattribute__(self, name)
AttributeError: 'DataFrame' object has no attribute 'append'
INFO:root:69 ended
ERROR:concurrent.futures:exception calling callback for <Future at 0x7fac21efd250 state=finished returned NoneType>
Traceback (most recent call last):
  File "/usr/lib/python3.8/concurrent/futures/_base.py", line 328, in _invoke_callbacks
    callback(self)
  File "/home/glima/Electrical-Behaviour-Prediction/SimulationManager/src/ExperimentManager.py", line 100, in <lambda>
    f.add_done_callback(lambda fut, i=idx: self.__callback(fut, i))
  File "/home/glima/Electrical-Behaviour-Prediction/SimulationManager/src/ExperimentManager.py", line 110, in __callback
    self.__completed.append(tmp_df)
  File "/home/glima/.local/lib/python3.8/site-packages/pandas/core/generic.py", line 5989, in __getattr__
    return object.__getattribute__(self, name)
AttributeError: 'DataFrame' object has no attribute 'append'
INFO:root:71 ended
ERROR:concurrent.futures:exception calling callback for <Future at 0x7fac21efd550 state=finished returned NoneType>
Traceback (most recent call last):
  File "/usr/lib/python3.8/concurrent/futures/_base.py", line 328, in _invoke_callbacks
    callback(self)
  File "/home/glima/Electrical-Behaviour-Prediction/SimulationManager/src/ExperimentManager.py", line 100, in <lambda>
    f.add_done_callback(lambda fut, i=idx: self.__callback(fut, i))
  File "/home/glima/Electrical-Behaviour-Prediction/SimulationManager/src/ExperimentManager.py", line 110, in __callback
    self.__completed.append(tmp_df)
  File "/home/glima/.local/lib/python3.8/site-packages/pandas/core/generic.py", line 5989, in __getattr__
    return object.__getattribute__(self, name)
AttributeError: 'DataFrame' object has no attribute 'append'
INFO:root:72 ended
ERROR:concurrent.futures:exception calling callback for <Future at 0x7fac21efd6a0 state=finished returned NoneType>
Traceback (most recent call last):
  File "/usr/lib/python3.8/concurrent/futures/_base.py", line 328, in _invoke_callbacks
    callback(self)
  File "/home/glima/Electrical-Behaviour-Prediction/SimulationManager/src/ExperimentManager.py", line 100, in <lambda>
    f.add_done_callback(lambda fut, i=idx: self.__callback(fut, i))
  File "/home/glima/Electrical-Behaviour-Prediction/SimulationManager/src/ExperimentManager.py", line 110, in __callback
    self.__completed.append(tmp_df)
  File "/home/glima/.local/lib/python3.8/site-packages/pandas/core/generic.py", line 5989, in __getattr__
    return object.__getattribute__(self, name)
AttributeError: 'DataFrame' object has no attribute 'append'
INFO:root:73 ended
ERROR:concurrent.futures:exception calling callback for <Future at 0x7fac21efd100 state=finished returned NoneType>
Traceback (most recent call last):
  File "/usr/lib/python3.8/concurrent/futures/_base.py", line 328, in _invoke_callbacks
    callback(self)
  File "/home/glima/Electrical-Behaviour-Prediction/SimulationManager/src/ExperimentManager.py", line 100, in <lambda>
    f.add_done_callback(lambda fut, i=idx: self.__callback(fut, i))
  File "/home/glima/Electrical-Behaviour-Prediction/SimulationManager/src/ExperimentManager.py", line 110, in __callback
    self.__completed.append(tmp_df)
  File "/home/glima/.local/lib/python3.8/site-packages/pandas/core/generic.py", line 5989, in __getattr__
    return object.__getattribute__(self, name)
AttributeError: 'DataFrame' object has no attribute 'append'
INFO:root:75 ended
ERROR:concurrent.futures:exception calling callback for <Future at 0x7fac21efda90 state=finished returned NoneType>
Traceback (most recent call last):
  File "/usr/lib/python3.8/concurrent/futures/_base.py", line 328, in _invoke_callbacks
    callback(self)
  File "/home/glima/Electrical-Behaviour-Prediction/SimulationManager/src/ExperimentManager.py", line 100, in <lambda>
    f.add_done_callback(lambda fut, i=idx: self.__callback(fut, i))
  File "/home/glima/Electrical-Behaviour-Prediction/SimulationManager/src/ExperimentManager.py", line 110, in __callback
    self.__completed.append(tmp_df)
  File "/home/glima/.local/lib/python3.8/site-packages/pandas/core/generic.py", line 5989, in __getattr__
    return object.__getattribute__(self, name)
AttributeError: 'DataFrame' object has no attribute 'append'
INFO:root:74 ended
ERROR:concurrent.futures:exception calling callback for <Future at 0x7fac21efd8e0 state=finished returned NoneType>
Traceback (most recent call last):
  File "/usr/lib/python3.8/concurrent/futures/_base.py", line 328, in _invoke_callbacks
    callback(self)
  File "/home/glima/Electrical-Behaviour-Prediction/SimulationManager/src/ExperimentManager.py", line 100, in <lambda>
    f.add_done_callback(lambda fut, i=idx: self.__callback(fut, i))
  File "/home/glima/Electrical-Behaviour-Prediction/SimulationManager/src/ExperimentManager.py", line 110, in __callback
    self.__completed.append(tmp_df)
  File "/home/glima/.local/lib/python3.8/site-packages/pandas/core/generic.py", line 5989, in __getattr__
    return object.__getattribute__(self, name)
AttributeError: 'DataFrame' object has no attribute 'append'
INFO:root:76 ended
ERROR:concurrent.futures:exception calling callback for <Future at 0x7fac21efdbe0 state=finished returned NoneType>
Traceback (most recent call last):
  File "/usr/lib/python3.8/concurrent/futures/_base.py", line 328, in _invoke_callbacks
    callback(self)
  File "/home/glima/Electrical-Behaviour-Prediction/SimulationManager/src/ExperimentManager.py", line 100, in <lambda>
    f.add_done_callback(lambda fut, i=idx: self.__callback(fut, i))
  File "/home/glima/Electrical-Behaviour-Prediction/SimulationManager/src/ExperimentManager.py", line 110, in __callback
    self.__completed.append(tmp_df)
  File "/home/glima/.local/lib/python3.8/site-packages/pandas/core/generic.py", line 5989, in __getattr__
    return object.__getattribute__(self, name)
AttributeError: 'DataFrame' object has no attribute 'append'
INFO:root:77 ended
ERROR:concurrent.futures:exception calling callback for <Future at 0x7fac21efdd30 state=finished returned NoneType>
Traceback (most recent call last):
  File "/usr/lib/python3.8/concurrent/futures/_base.py", line 328, in _invoke_callbacks
    callback(self)
  File "/home/glima/Electrical-Behaviour-Prediction/SimulationManager/src/ExperimentManager.py", line 100, in <lambda>
    f.add_done_callback(lambda fut, i=idx: self.__callback(fut, i))
  File "/home/glima/Electrical-Behaviour-Prediction/SimulationManager/src/ExperimentManager.py", line 110, in __callback
    self.__completed.append(tmp_df)
  File "/home/glima/.local/lib/python3.8/site-packages/pandas/core/generic.py", line 5989, in __getattr__
    return object.__getattribute__(self, name)
AttributeError: 'DataFrame' object has no attribute 'append'
INFO:root:78 ended
ERROR:concurrent.futures:exception calling callback for <Future at 0x7fac21efde80 state=finished returned NoneType>
Traceback (most recent call last):
  File "/usr/lib/python3.8/concurrent/futures/_base.py", line 328, in _invoke_callbacks
    callback(self)
  File "/home/glima/Electrical-Behaviour-Prediction/SimulationManager/src/ExperimentManager.py", line 100, in <lambda>
    f.add_done_callback(lambda fut, i=idx: self.__callback(fut, i))
  File "/home/glima/Electrical-Behaviour-Prediction/SimulationManager/src/ExperimentManager.py", line 110, in __callback
    self.__completed.append(tmp_df)
  File "/home/glima/.local/lib/python3.8/site-packages/pandas/core/generic.py", line 5989, in __getattr__
    return object.__getattribute__(self, name)
AttributeError: 'DataFrame' object has no attribute 'append'
INFO:root:79 ended
ERROR:concurrent.futures:exception calling callback for <Future at 0x7fac21efdfd0 state=finished returned NoneType>
Traceback (most recent call last):
  File "/usr/lib/python3.8/concurrent/futures/_base.py", line 328, in _invoke_callbacks
    callback(self)
  File "/home/glima/Electrical-Behaviour-Prediction/SimulationManager/src/ExperimentManager.py", line 100, in <lambda>
    f.add_done_callback(lambda fut, i=idx: self.__callback(fut, i))
  File "/home/glima/Electrical-Behaviour-Prediction/SimulationManager/src/ExperimentManager.py", line 110, in __callback
    self.__completed.append(tmp_df)
  File "/home/glima/.local/lib/python3.8/site-packages/pandas/core/generic.py", line 5989, in __getattr__
    return object.__getattribute__(self, name)
AttributeError: 'DataFrame' object has no attribute 'append'
