INFO:root:Starting experiment
INFO:root:Running 0
INFO:root:Running 1
INFO:root:Running 2
INFO:root:Running 3
INFO:root:Running 4
INFO:root:Running 5
INFO:root:Running 6
INFO:root:starting FET_INVERTER/results/0
INFO:root:Running 7
INFO:root:starting FET_INVERTER/results/1
INFO:root:Running 8
INFO:root:starting FET_INVERTER/results/5
INFO:root:starting FET_INVERTER/results/2
INFO:root:starting FET_INVERTER/results/4
INFO:root:starting FET_INVERTER/results/3
INFO:root:Running 9
INFO:root:Running 10
INFO:root:Running 11
INFO:root:Running 12
INFO:root:Running 13
INFO:root:Running 14
INFO:root:Running 15
INFO:root:Running 16
INFO:root:Running 17
INFO:root:Running 18
INFO:root:Running 19
INFO:root:Running 20
INFO:root:Running 21
INFO:root:Running 22
INFO:root:Running 23
INFO:root:Running 24
INFO:root:Running 25
INFO:root:Running 26
INFO:root:Running 27
INFO:root:Running 28
INFO:root:Running 29
INFO:root:Running 30
INFO:root:Running 31
INFO:root:starting FET_INVERTER/results/6
INFO:root:3 ended
INFO:root:starting FET_INVERTER/results/7
ERROR:concurrent.futures:exception calling callback for <Future at 0x7f35adce4dc0 state=finished returned NoneType>
Traceback (most recent call last):
  File "/usr/lib/python3.8/concurrent/futures/_base.py", line 328, in _invoke_callbacks
    callback(self)
  File "/home/glima/glima_old/Electrical-Behaviour-Prediction/FINFET/7nm/ExperimentManager.py", line 86, in <lambda>
    f.add_done_callback(lambda fut, i=idx: self.__callback(fut, i))
  File "/home/glima/glima_old/Electrical-Behaviour-Prediction/FINFET/7nm/ExperimentManager.py", line 96, in __callback
    self.__completed.append(tmp_df)
  File "/home/glima/.local/lib/python3.8/site-packages/pandas/core/generic.py", line 5989, in __getattr__
    return object.__getattribute__(self, name)
AttributeError: 'DataFrame' object has no attribute 'append'
INFO:root:4 ended
ERROR:concurrent.futures:exception calling callback for <Future at 0x7f35adce4f10 state=finished returned NoneType>
Traceback (most recent call last):
  File "/usr/lib/python3.8/concurrent/futures/_base.py", line 328, in _invoke_callbacks
    callback(self)
  File "/home/glima/glima_old/Electrical-Behaviour-Prediction/FINFET/7nm/ExperimentManager.py", line 86, in <lambda>
    f.add_done_callback(lambda fut, i=idx: self.__callback(fut, i))
  File "/home/glima/glima_old/Electrical-Behaviour-Prediction/FINFET/7nm/ExperimentManager.py", line 96, in __callback
    self.__completed.append(tmp_df)
  File "/home/glima/.local/lib/python3.8/site-packages/pandas/core/generic.py", line 5989, in __getattr__
    return object.__getattribute__(self, name)
AttributeError: 'DataFrame' object has no attribute 'append'
INFO:root:1 ended
INFO:root:starting FET_INVERTER/results/8
INFO:root:starting FET_INVERTER/results/9
ERROR:concurrent.futures:exception calling callback for <Future at 0x7f35adce4a90 state=finished returned NoneType>
Traceback (most recent call last):
  File "/usr/lib/python3.8/concurrent/futures/_base.py", line 328, in _invoke_callbacks
    callback(self)
  File "/home/glima/glima_old/Electrical-Behaviour-Prediction/FINFET/7nm/ExperimentManager.py", line 86, in <lambda>
    f.add_done_callback(lambda fut, i=idx: self.__callback(fut, i))
  File "/home/glima/glima_old/Electrical-Behaviour-Prediction/FINFET/7nm/ExperimentManager.py", line 96, in __callback
    self.__completed.append(tmp_df)
  File "/home/glima/.local/lib/python3.8/site-packages/pandas/core/generic.py", line 5989, in __getattr__
    return object.__getattribute__(self, name)
AttributeError: 'DataFrame' object has no attribute 'append'
INFO:root:0 ended
ERROR:concurrent.futures:exception calling callback for <Future at 0x7f35add4f910 state=finished returned NoneType>
Traceback (most recent call last):
  File "/usr/lib/python3.8/concurrent/futures/_base.py", line 328, in _invoke_callbacks
    callback(self)
  File "/home/glima/glima_old/Electrical-Behaviour-Prediction/FINFET/7nm/ExperimentManager.py", line 86, in <lambda>
    f.add_done_callback(lambda fut, i=idx: self.__callback(fut, i))
  File "/home/glima/glima_old/Electrical-Behaviour-Prediction/FINFET/7nm/ExperimentManager.py", line 96, in __callback
    self.__completed.append(tmp_df)
  File "/home/glima/.local/lib/python3.8/site-packages/pandas/core/generic.py", line 5989, in __getattr__
    return object.__getattribute__(self, name)
AttributeError: 'DataFrame' object has no attribute 'append'
INFO:root:starting FET_INVERTER/results/10
INFO:root:5 ended
ERROR:concurrent.futures:exception calling callback for <Future at 0x7f35adce4e50 state=finished returned NoneType>
Traceback (most recent call last):
  File "/usr/lib/python3.8/concurrent/futures/_base.py", line 328, in _invoke_callbacks
    callback(self)
  File "/home/glima/glima_old/Electrical-Behaviour-Prediction/FINFET/7nm/ExperimentManager.py", line 86, in <lambda>
    f.add_done_callback(lambda fut, i=idx: self.__callback(fut, i))
  File "/home/glima/glima_old/Electrical-Behaviour-Prediction/FINFET/7nm/ExperimentManager.py", line 96, in __callback
    self.__completed.append(tmp_df)
  File "/home/glima/.local/lib/python3.8/site-packages/pandas/core/generic.py", line 5989, in __getattr__
    return object.__getattribute__(self, name)
AttributeError: 'DataFrame' object has no attribute 'append'
INFO:root:2 ended
INFO:root:starting FET_INVERTER/results/11
ERROR:concurrent.futures:exception calling callback for <Future at 0x7f35adce4c70 state=finished returned NoneType>
Traceback (most recent call last):
  File "/usr/lib/python3.8/concurrent/futures/_base.py", line 328, in _invoke_callbacks
    callback(self)
  File "/home/glima/glima_old/Electrical-Behaviour-Prediction/FINFET/7nm/ExperimentManager.py", line 86, in <lambda>
    f.add_done_callback(lambda fut, i=idx: self.__callback(fut, i))
  File "/home/glima/glima_old/Electrical-Behaviour-Prediction/FINFET/7nm/ExperimentManager.py", line 96, in __callback
    self.__completed.append(tmp_df)
  File "/home/glima/.local/lib/python3.8/site-packages/pandas/core/generic.py", line 5989, in __getattr__
    return object.__getattribute__(self, name)
AttributeError: 'DataFrame' object has no attribute 'append'
INFO:root:starting FET_INVERTER/results/12
INFO:root:6 ended
ERROR:concurrent.futures:exception calling callback for <Future at 0x7f35adce4970 state=finished returned NoneType>
Traceback (most recent call last):
  File "/usr/lib/python3.8/concurrent/futures/_base.py", line 328, in _invoke_callbacks
    callback(self)
  File "/home/glima/glima_old/Electrical-Behaviour-Prediction/FINFET/7nm/ExperimentManager.py", line 86, in <lambda>
    f.add_done_callback(lambda fut, i=idx: self.__callback(fut, i))
  File "/home/glima/glima_old/Electrical-Behaviour-Prediction/FINFET/7nm/ExperimentManager.py", line 96, in __callback
    self.__completed.append(tmp_df)
  File "/home/glima/.local/lib/python3.8/site-packages/pandas/core/generic.py", line 5989, in __getattr__
    return object.__getattribute__(self, name)
AttributeError: 'DataFrame' object has no attribute 'append'
INFO:root:starting FET_INVERTER/results/13
INFO:root:10 ended
INFO:root:starting FET_INVERTER/results/14
ERROR:concurrent.futures:exception calling callback for <Future at 0x7f35adcec5e0 state=finished returned NoneType>
Traceback (most recent call last):
  File "/usr/lib/python3.8/concurrent/futures/_base.py", line 328, in _invoke_callbacks
    callback(self)
  File "/home/glima/glima_old/Electrical-Behaviour-Prediction/FINFET/7nm/ExperimentManager.py", line 86, in <lambda>
    f.add_done_callback(lambda fut, i=idx: self.__callback(fut, i))
  File "/home/glima/glima_old/Electrical-Behaviour-Prediction/FINFET/7nm/ExperimentManager.py", line 96, in __callback
    self.__completed.append(tmp_df)
  File "/home/glima/.local/lib/python3.8/site-packages/pandas/core/generic.py", line 5989, in __getattr__
    return object.__getattribute__(self, name)
AttributeError: 'DataFrame' object has no attribute 'append'
INFO:root:7 ended
ERROR:concurrent.futures:exception calling callback for <Future at 0x7f35adce4580 state=finished returned NoneType>
Traceback (most recent call last):
  File "/usr/lib/python3.8/concurrent/futures/_base.py", line 328, in _invoke_callbacks
    callback(self)
  File "/home/glima/glima_old/Electrical-Behaviour-Prediction/FINFET/7nm/ExperimentManager.py", line 86, in <lambda>
    f.add_done_callback(lambda fut, i=idx: self.__callback(fut, i))
  File "/home/glima/glima_old/Electrical-Behaviour-Prediction/FINFET/7nm/ExperimentManager.py", line 96, in __callback
    self.__completed.append(tmp_df)
  File "/home/glima/.local/lib/python3.8/site-packages/pandas/core/generic.py", line 5989, in __getattr__
    return object.__getattribute__(self, name)
AttributeError: 'DataFrame' object has no attribute 'append'
INFO:root:11 ended
INFO:root:starting FET_INVERTER/results/15
ERROR:concurrent.futures:exception calling callback for <Future at 0x7f35adcec8e0 state=finished returned NoneType>
Traceback (most recent call last):
  File "/usr/lib/python3.8/concurrent/futures/_base.py", line 328, in _invoke_callbacks
    callback(self)
  File "/home/glima/glima_old/Electrical-Behaviour-Prediction/FINFET/7nm/ExperimentManager.py", line 86, in <lambda>
    f.add_done_callback(lambda fut, i=idx: self.__callback(fut, i))
  File "/home/glima/glima_old/Electrical-Behaviour-Prediction/FINFET/7nm/ExperimentManager.py", line 96, in __callback
    self.__completed.append(tmp_df)
  File "/home/glima/.local/lib/python3.8/site-packages/pandas/core/generic.py", line 5989, in __getattr__
    return object.__getattribute__(self, name)
AttributeError: 'DataFrame' object has no attribute 'append'
INFO:root:starting FET_INVERTER/results/16
INFO:root:9 ended
ERROR:concurrent.futures:exception calling callback for <Future at 0x7f35adcec640 state=finished returned NoneType>
Traceback (most recent call last):
  File "/usr/lib/python3.8/concurrent/futures/_base.py", line 328, in _invoke_callbacks
    callback(self)
  File "/home/glima/glima_old/Electrical-Behaviour-Prediction/FINFET/7nm/ExperimentManager.py", line 86, in <lambda>
    f.add_done_callback(lambda fut, i=idx: self.__callback(fut, i))
  File "/home/glima/glima_old/Electrical-Behaviour-Prediction/FINFET/7nm/ExperimentManager.py", line 96, in __callback
    self.__completed.append(tmp_df)
  File "/home/glima/.local/lib/python3.8/site-packages/pandas/core/generic.py", line 5989, in __getattr__
    return object.__getattribute__(self, name)
AttributeError: 'DataFrame' object has no attribute 'append'
INFO:root:8 ended
INFO:root:starting FET_INVERTER/results/17
ERROR:concurrent.futures:exception calling callback for <Future at 0x7f35adcec1f0 state=finished returned NoneType>
Traceback (most recent call last):
  File "/usr/lib/python3.8/concurrent/futures/_base.py", line 328, in _invoke_callbacks
    callback(self)
  File "/home/glima/glima_old/Electrical-Behaviour-Prediction/FINFET/7nm/ExperimentManager.py", line 86, in <lambda>
    f.add_done_callback(lambda fut, i=idx: self.__callback(fut, i))
  File "/home/glima/glima_old/Electrical-Behaviour-Prediction/FINFET/7nm/ExperimentManager.py", line 96, in __callback
    self.__completed.append(tmp_df)
  File "/home/glima/.local/lib/python3.8/site-packages/pandas/core/generic.py", line 5989, in __getattr__
    return object.__getattribute__(self, name)
AttributeError: 'DataFrame' object has no attribute 'append'
INFO:root:16 ended
INFO:root:starting FET_INVERTER/results/18
INFO:root:starting FET_INVERTER/results/19
ERROR:concurrent.futures:exception calling callback for <Future at 0x7f35adcecf10 state=finished returned NoneType>
Traceback (most recent call last):
  File "/usr/lib/python3.8/concurrent/futures/_base.py", line 328, in _invoke_callbacks
    callback(self)
  File "/home/glima/glima_old/Electrical-Behaviour-Prediction/FINFET/7nm/ExperimentManager.py", line 86, in <lambda>
    f.add_done_callback(lambda fut, i=idx: self.__callback(fut, i))
  File "/home/glima/glima_old/Electrical-Behaviour-Prediction/FINFET/7nm/ExperimentManager.py", line 96, in __callback
    self.__completed.append(tmp_df)
  File "/home/glima/.local/lib/python3.8/site-packages/pandas/core/generic.py", line 5989, in __getattr__
    return object.__getattribute__(self, name)
AttributeError: 'DataFrame' object has no attribute 'append'
INFO:root:15 ended
ERROR:concurrent.futures:exception calling callback for <Future at 0x7f35adcecdc0 state=finished returned NoneType>
Traceback (most recent call last):
  File "/usr/lib/python3.8/concurrent/futures/_base.py", line 328, in _invoke_callbacks
    callback(self)
  File "/home/glima/glima_old/Electrical-Behaviour-Prediction/FINFET/7nm/ExperimentManager.py", line 86, in <lambda>
    f.add_done_callback(lambda fut, i=idx: self.__callback(fut, i))
  File "/home/glima/glima_old/Electrical-Behaviour-Prediction/FINFET/7nm/ExperimentManager.py", line 96, in __callback
    self.__completed.append(tmp_df)
  File "/home/glima/.local/lib/python3.8/site-packages/pandas/core/generic.py", line 5989, in __getattr__
    return object.__getattribute__(self, name)
AttributeError: 'DataFrame' object has no attribute 'append'
INFO:root:12 ended
INFO:root:starting FET_INVERTER/results/20
ERROR:concurrent.futures:exception calling callback for <Future at 0x7f35adceca30 state=finished returned NoneType>
Traceback (most recent call last):
  File "/usr/lib/python3.8/concurrent/futures/_base.py", line 328, in _invoke_callbacks
    callback(self)
  File "/home/glima/glima_old/Electrical-Behaviour-Prediction/FINFET/7nm/ExperimentManager.py", line 86, in <lambda>
    f.add_done_callback(lambda fut, i=idx: self.__callback(fut, i))
  File "/home/glima/glima_old/Electrical-Behaviour-Prediction/FINFET/7nm/ExperimentManager.py", line 96, in __callback
    self.__completed.append(tmp_df)
  File "/home/glima/.local/lib/python3.8/site-packages/pandas/core/generic.py", line 5989, in __getattr__
    return object.__getattribute__(self, name)
AttributeError: 'DataFrame' object has no attribute 'append'
INFO:root:starting FET_INVERTER/results/21
INFO:root:13 ended
ERROR:concurrent.futures:exception calling callback for <Future at 0x7f35adcec520 state=finished returned NoneType>
Traceback (most recent call last):
  File "/usr/lib/python3.8/concurrent/futures/_base.py", line 328, in _invoke_callbacks
    callback(self)
  File "/home/glima/glima_old/Electrical-Behaviour-Prediction/FINFET/7nm/ExperimentManager.py", line 86, in <lambda>
    f.add_done_callback(lambda fut, i=idx: self.__callback(fut, i))
  File "/home/glima/glima_old/Electrical-Behaviour-Prediction/FINFET/7nm/ExperimentManager.py", line 96, in __callback
    self.__completed.append(tmp_df)
  File "/home/glima/.local/lib/python3.8/site-packages/pandas/core/generic.py", line 5989, in __getattr__
    return object.__getattribute__(self, name)
AttributeError: 'DataFrame' object has no attribute 'append'
INFO:root:17 ended
INFO:root:starting FET_INVERTER/results/22
ERROR:concurrent.futures:exception calling callback for <Future at 0x7f35adcece50 state=finished returned NoneType>
Traceback (most recent call last):
  File "/usr/lib/python3.8/concurrent/futures/_base.py", line 328, in _invoke_callbacks
    callback(self)
  File "/home/glima/glima_old/Electrical-Behaviour-Prediction/FINFET/7nm/ExperimentManager.py", line 86, in <lambda>
    f.add_done_callback(lambda fut, i=idx: self.__callback(fut, i))
  File "/home/glima/glima_old/Electrical-Behaviour-Prediction/FINFET/7nm/ExperimentManager.py", line 96, in __callback
    self.__completed.append(tmp_df)
  File "/home/glima/.local/lib/python3.8/site-packages/pandas/core/generic.py", line 5989, in __getattr__
    return object.__getattribute__(self, name)
AttributeError: 'DataFrame' object has no attribute 'append'
INFO:root:14 ended
INFO:root:starting FET_INVERTER/results/23
ERROR:concurrent.futures:exception calling callback for <Future at 0x7f35adcecc70 state=finished returned NoneType>
Traceback (most recent call last):
  File "/usr/lib/python3.8/concurrent/futures/_base.py", line 328, in _invoke_callbacks
    callback(self)
  File "/home/glima/glima_old/Electrical-Behaviour-Prediction/FINFET/7nm/ExperimentManager.py", line 86, in <lambda>
    f.add_done_callback(lambda fut, i=idx: self.__callback(fut, i))
  File "/home/glima/glima_old/Electrical-Behaviour-Prediction/FINFET/7nm/ExperimentManager.py", line 96, in __callback
    self.__completed.append(tmp_df)
  File "/home/glima/.local/lib/python3.8/site-packages/pandas/core/generic.py", line 5989, in __getattr__
    return object.__getattribute__(self, name)
AttributeError: 'DataFrame' object has no attribute 'append'
INFO:root:22 ended
INFO:root:starting FET_INVERTER/results/24
ERROR:concurrent.futures:exception calling callback for <Future at 0x7f35adcf4730 state=finished returned NoneType>
Traceback (most recent call last):
  File "/usr/lib/python3.8/concurrent/futures/_base.py", line 328, in _invoke_callbacks
    callback(self)
  File "/home/glima/glima_old/Electrical-Behaviour-Prediction/FINFET/7nm/ExperimentManager.py", line 86, in <lambda>
    f.add_done_callback(lambda fut, i=idx: self.__callback(fut, i))
  File "/home/glima/glima_old/Electrical-Behaviour-Prediction/FINFET/7nm/ExperimentManager.py", line 96, in __callback
    self.__completed.append(tmp_df)
  File "/home/glima/.local/lib/python3.8/site-packages/pandas/core/generic.py", line 5989, in __getattr__
    return object.__getattribute__(self, name)
AttributeError: 'DataFrame' object has no attribute 'append'
INFO:root:18 ended
INFO:root:starting FET_INVERTER/results/25
ERROR:concurrent.futures:exception calling callback for <Future at 0x7f35adcf4160 state=finished returned NoneType>
Traceback (most recent call last):
  File "/usr/lib/python3.8/concurrent/futures/_base.py", line 328, in _invoke_callbacks
    callback(self)
  File "/home/glima/glima_old/Electrical-Behaviour-Prediction/FINFET/7nm/ExperimentManager.py", line 86, in <lambda>
    f.add_done_callback(lambda fut, i=idx: self.__callback(fut, i))
  File "/home/glima/glima_old/Electrical-Behaviour-Prediction/FINFET/7nm/ExperimentManager.py", line 96, in __callback
    self.__completed.append(tmp_df)
  File "/home/glima/.local/lib/python3.8/site-packages/pandas/core/generic.py", line 5989, in __getattr__
    return object.__getattribute__(self, name)
AttributeError: 'DataFrame' object has no attribute 'append'
INFO:root:20 ended
INFO:root:starting FET_INVERTER/results/26
ERROR:concurrent.futures:exception calling callback for <Future at 0x7f35adcf4490 state=finished returned NoneType>
Traceback (most recent call last):
  File "/usr/lib/python3.8/concurrent/futures/_base.py", line 328, in _invoke_callbacks
    callback(self)
  File "/home/glima/glima_old/Electrical-Behaviour-Prediction/FINFET/7nm/ExperimentManager.py", line 86, in <lambda>
    f.add_done_callback(lambda fut, i=idx: self.__callback(fut, i))
  File "/home/glima/glima_old/Electrical-Behaviour-Prediction/FINFET/7nm/ExperimentManager.py", line 96, in __callback
    self.__completed.append(tmp_df)
  File "/home/glima/.local/lib/python3.8/site-packages/pandas/core/generic.py", line 5989, in __getattr__
    return object.__getattribute__(self, name)
AttributeError: 'DataFrame' object has no attribute 'append'
INFO:root:23 ended
INFO:root:starting FET_INVERTER/results/27
INFO:root:starting FET_INVERTER/results/28
ERROR:concurrent.futures:exception calling callback for <Future at 0x7f35adcf4880 state=finished returned NoneType>
Traceback (most recent call last):
  File "/usr/lib/python3.8/concurrent/futures/_base.py", line 328, in _invoke_callbacks
    callback(self)
  File "/home/glima/glima_old/Electrical-Behaviour-Prediction/FINFET/7nm/ExperimentManager.py", line 86, in <lambda>
    f.add_done_callback(lambda fut, i=idx: self.__callback(fut, i))
  File "/home/glima/glima_old/Electrical-Behaviour-Prediction/FINFET/7nm/ExperimentManager.py", line 96, in __callback
    self.__completed.append(tmp_df)
  File "/home/glima/.local/lib/python3.8/site-packages/pandas/core/generic.py", line 5989, in __getattr__
    return object.__getattribute__(self, name)
AttributeError: 'DataFrame' object has no attribute 'append'
INFO:root:19 ended
ERROR:concurrent.futures:exception calling callback for <Future at 0x7f35adcf4340 state=finished returned NoneType>
Traceback (most recent call last):
  File "/usr/lib/python3.8/concurrent/futures/_base.py", line 328, in _invoke_callbacks
    callback(self)
  File "/home/glima/glima_old/Electrical-Behaviour-Prediction/FINFET/7nm/ExperimentManager.py", line 86, in <lambda>
    f.add_done_callback(lambda fut, i=idx: self.__callback(fut, i))
  File "/home/glima/glima_old/Electrical-Behaviour-Prediction/FINFET/7nm/ExperimentManager.py", line 96, in __callback
    self.__completed.append(tmp_df)
  File "/home/glima/.local/lib/python3.8/site-packages/pandas/core/generic.py", line 5989, in __getattr__
    return object.__getattribute__(self, name)
AttributeError: 'DataFrame' object has no attribute 'append'
INFO:root:starting FET_INVERTER/results/29
INFO:root:21 ended
ERROR:concurrent.futures:exception calling callback for <Future at 0x7f35adcf45e0 state=finished returned NoneType>
Traceback (most recent call last):
  File "/usr/lib/python3.8/concurrent/futures/_base.py", line 328, in _invoke_callbacks
    callback(self)
  File "/home/glima/glima_old/Electrical-Behaviour-Prediction/FINFET/7nm/ExperimentManager.py", line 86, in <lambda>
    f.add_done_callback(lambda fut, i=idx: self.__callback(fut, i))
  File "/home/glima/glima_old/Electrical-Behaviour-Prediction/FINFET/7nm/ExperimentManager.py", line 96, in __callback
    self.__completed.append(tmp_df)
  File "/home/glima/.local/lib/python3.8/site-packages/pandas/core/generic.py", line 5989, in __getattr__
    return object.__getattribute__(self, name)
AttributeError: 'DataFrame' object has no attribute 'append'
INFO:root:starting FET_INVERTER/results/30
INFO:root:27 ended
INFO:root:starting FET_INVERTER/results/31
ERROR:concurrent.futures:exception calling callback for <Future at 0x7f35adcf4dc0 state=finished returned NoneType>
Traceback (most recent call last):
  File "/usr/lib/python3.8/concurrent/futures/_base.py", line 328, in _invoke_callbacks
    callback(self)
  File "/home/glima/glima_old/Electrical-Behaviour-Prediction/FINFET/7nm/ExperimentManager.py", line 86, in <lambda>
    f.add_done_callback(lambda fut, i=idx: self.__callback(fut, i))
  File "/home/glima/glima_old/Electrical-Behaviour-Prediction/FINFET/7nm/ExperimentManager.py", line 96, in __callback
    self.__completed.append(tmp_df)
  File "/home/glima/.local/lib/python3.8/site-packages/pandas/core/generic.py", line 5989, in __getattr__
    return object.__getattribute__(self, name)
AttributeError: 'DataFrame' object has no attribute 'append'
INFO:root:28 ended
ERROR:concurrent.futures:exception calling callback for <Future at 0x7f35adcf4f10 state=finished returned NoneType>
Traceback (most recent call last):
  File "/usr/lib/python3.8/concurrent/futures/_base.py", line 328, in _invoke_callbacks
    callback(self)
  File "/home/glima/glima_old/Electrical-Behaviour-Prediction/FINFET/7nm/ExperimentManager.py", line 86, in <lambda>
    f.add_done_callback(lambda fut, i=idx: self.__callback(fut, i))
  File "/home/glima/glima_old/Electrical-Behaviour-Prediction/FINFET/7nm/ExperimentManager.py", line 96, in __callback
    self.__completed.append(tmp_df)
  File "/home/glima/.local/lib/python3.8/site-packages/pandas/core/generic.py", line 5989, in __getattr__
    return object.__getattribute__(self, name)
AttributeError: 'DataFrame' object has no attribute 'append'
INFO:root:26 ended
ERROR:concurrent.futures:exception calling callback for <Future at 0x7f35adcf4c70 state=finished returned NoneType>
Traceback (most recent call last):
  File "/usr/lib/python3.8/concurrent/futures/_base.py", line 328, in _invoke_callbacks
    callback(self)
  File "/home/glima/glima_old/Electrical-Behaviour-Prediction/FINFET/7nm/ExperimentManager.py", line 86, in <lambda>
    f.add_done_callback(lambda fut, i=idx: self.__callback(fut, i))
  File "/home/glima/glima_old/Electrical-Behaviour-Prediction/FINFET/7nm/ExperimentManager.py", line 96, in __callback
    self.__completed.append(tmp_df)
  File "/home/glima/.local/lib/python3.8/site-packages/pandas/core/generic.py", line 5989, in __getattr__
    return object.__getattribute__(self, name)
AttributeError: 'DataFrame' object has no attribute 'append'
INFO:root:24 ended
ERROR:concurrent.futures:exception calling callback for <Future at 0x7f35adcf49d0 state=finished returned NoneType>
Traceback (most recent call last):
  File "/usr/lib/python3.8/concurrent/futures/_base.py", line 328, in _invoke_callbacks
    callback(self)
  File "/home/glima/glima_old/Electrical-Behaviour-Prediction/FINFET/7nm/ExperimentManager.py", line 86, in <lambda>
    f.add_done_callback(lambda fut, i=idx: self.__callback(fut, i))
  File "/home/glima/glima_old/Electrical-Behaviour-Prediction/FINFET/7nm/ExperimentManager.py", line 96, in __callback
    self.__completed.append(tmp_df)
  File "/home/glima/.local/lib/python3.8/site-packages/pandas/core/generic.py", line 5989, in __getattr__
    return object.__getattribute__(self, name)
AttributeError: 'DataFrame' object has no attribute 'append'
INFO:root:29 ended
ERROR:concurrent.futures:exception calling callback for <Future at 0x7f35adcf4e50 state=finished returned NoneType>
Traceback (most recent call last):
  File "/usr/lib/python3.8/concurrent/futures/_base.py", line 328, in _invoke_callbacks
    callback(self)
  File "/home/glima/glima_old/Electrical-Behaviour-Prediction/FINFET/7nm/ExperimentManager.py", line 86, in <lambda>
    f.add_done_callback(lambda fut, i=idx: self.__callback(fut, i))
  File "/home/glima/glima_old/Electrical-Behaviour-Prediction/FINFET/7nm/ExperimentManager.py", line 96, in __callback
    self.__completed.append(tmp_df)
  File "/home/glima/.local/lib/python3.8/site-packages/pandas/core/generic.py", line 5989, in __getattr__
    return object.__getattribute__(self, name)
AttributeError: 'DataFrame' object has no attribute 'append'
INFO:root:25 ended
ERROR:concurrent.futures:exception calling callback for <Future at 0x7f35adcf4b20 state=finished returned NoneType>
Traceback (most recent call last):
  File "/usr/lib/python3.8/concurrent/futures/_base.py", line 328, in _invoke_callbacks
    callback(self)
  File "/home/glima/glima_old/Electrical-Behaviour-Prediction/FINFET/7nm/ExperimentManager.py", line 86, in <lambda>
    f.add_done_callback(lambda fut, i=idx: self.__callback(fut, i))
  File "/home/glima/glima_old/Electrical-Behaviour-Prediction/FINFET/7nm/ExperimentManager.py", line 96, in __callback
    self.__completed.append(tmp_df)
  File "/home/glima/.local/lib/python3.8/site-packages/pandas/core/generic.py", line 5989, in __getattr__
    return object.__getattribute__(self, name)
AttributeError: 'DataFrame' object has no attribute 'append'
INFO:root:30 ended
ERROR:concurrent.futures:exception calling callback for <Future at 0x7f35adcfa160 state=finished returned NoneType>
Traceback (most recent call last):
  File "/usr/lib/python3.8/concurrent/futures/_base.py", line 328, in _invoke_callbacks
    callback(self)
  File "/home/glima/glima_old/Electrical-Behaviour-Prediction/FINFET/7nm/ExperimentManager.py", line 86, in <lambda>
    f.add_done_callback(lambda fut, i=idx: self.__callback(fut, i))
  File "/home/glima/glima_old/Electrical-Behaviour-Prediction/FINFET/7nm/ExperimentManager.py", line 96, in __callback
    self.__completed.append(tmp_df)
  File "/home/glima/.local/lib/python3.8/site-packages/pandas/core/generic.py", line 5989, in __getattr__
    return object.__getattribute__(self, name)
AttributeError: 'DataFrame' object has no attribute 'append'
INFO:root:31 ended
ERROR:concurrent.futures:exception calling callback for <Future at 0x7f35adcfa340 state=finished returned NoneType>
Traceback (most recent call last):
  File "/usr/lib/python3.8/concurrent/futures/_base.py", line 328, in _invoke_callbacks
    callback(self)
  File "/home/glima/glima_old/Electrical-Behaviour-Prediction/FINFET/7nm/ExperimentManager.py", line 86, in <lambda>
    f.add_done_callback(lambda fut, i=idx: self.__callback(fut, i))
  File "/home/glima/glima_old/Electrical-Behaviour-Prediction/FINFET/7nm/ExperimentManager.py", line 96, in __callback
    self.__completed.append(tmp_df)
  File "/home/glima/.local/lib/python3.8/site-packages/pandas/core/generic.py", line 5989, in __getattr__
    return object.__getattribute__(self, name)
AttributeError: 'DataFrame' object has no attribute 'append'
